Workbook

Sheet Cuotas Estudiantes Pregrado
A2: MUESTRA POR SEMESTRE PREGRADO
A3: NOMBRE DEL PROGRAMA | B3: SEMESTRE 2 | C3: SEMESTRE 3 | D3: SEMESTRE 4 | E3: SEMESTRE 5 | F3: SEMESTRE 6 | G3: SEMESTRE 7 | H3: SEMESTRE 8 | I3: SEMESTRE 9 | J3: SEMESTRE 10 | K3: SEMESTRE 11 | L3: SEMESTRE 12 | M3: TOTAL POBLACIÓN | N3: MUESTRA | O3: ALCANCE | P3: ME (95%)
A4: Administración & Servicio | B4: 10 | C4: 9 | D4: 7 | E4: 9 | F4: 12 | G4: 12 | H4: 12 | M4: 84 | N4: =SUM(B4:L4) -> 71 | O4: =N4/M4 -> 0.8452381 | P4: =IFERROR((((1.96^2*0.5*0.5*($M4-N4))/(N4*($M4-1)))^0.5),"") -> 0.046028787
A5: Administración de Empresas | B5: 24 | C5: 24 | D5: 21 | E5: 22 | F5: 19 | G5: 23 | H5: 29 | M5: 253 | N5: =SUM(B5:L5) -> 162 | O5: =N5/M5 -> 0.64031621 | P5: =IFERROR((((1.96^2*0.5*0.5*($M5-N5))/(N5*($M5-1)))^0.5),"") -> 0.046268881
A6: Administración de Mercadeo y Logística Internacionales | B6: 34 | C6: 22 | D6: 37 | E6: 28 | F6: 29 | G6: 20 | H6: 25 | M6: 344 | N6: =SUM(B6:L6) -> 195 | O6: =N6/M6 -> 0.56686047 | P6: =IFERROR((((1.96^2*0.5*0.5*($M6-N6))/(N6*($M6-1)))^0.5),"") -> 0.046254591
A7: Administración de Negocios Internacionales | B7: 47 | C7: 36 | D7: 37 | E7: 34 | F7: 39 | G7: 28 | H7: 33 | M7: 580 | N7: =SUM(B7:L7) -> 254 | O7: =N7/M7 -> 0.43793103 | P7: =IFERROR((((1.96^2*0.5*0.5*($M7-N7))/(N7*($M7-1)))^0.5),"") -> 0.046140122
A8: Economía y Finanzas Internacionales | B8: 32 | C8: 26 | D8: 21 | E8: 13 | F8: 18 | G8: 11 | H8: 25 | M8: 215 | N8: =SUM(B8:L8) -> 146 | O8: =N8/M8 -> 0.67906977 | P8: =IFERROR((((1.96^2*0.5*0.5*($M8-N8))/(N8*($M8-1)))^0.5),"") -> 0.046053995
A9: Gastronomía | B9: 41 | C9: 16 | D9: 27 | E9: 22 | F9: 19 | G9: 15 | H9: 18 | M9: 240 | N9: =SUM(B9:L9) -> 158 | O9: =N9/M9 -> 0.65833333 | P9: =IFERROR((((1.96^2*0.5*0.5*($M9-N9))/(N9*($M9-1)))^0.5),"") -> 0.045667318
A10: Comunicación Corporativa | B10: 19 | C10: 25 | D10: 21 | E10: 19 | F10: 24 | G10: 13 | H10: 21 | M10: 206 | N10: =SUM(B10:L10) -> 142 | O10: =N10/M10 -> 0.68932039 | P10: =IFERROR((((1.96^2*0.5*0.5*($M10-N10))/(N10*($M10-1)))^0.5),"") -> 0.045950999
A11: Comunicación Audiovisual y Multimedios | B11: 39 | C11: 49 | D11: 37 | E11: 38 | F11: 30 | G11: 34 | H11: 32 | M11: 606 | N11: =SUM(B11:L11) -> 259 | O11: =N11/M11 -> 0.42739274 | P11: =IFERROR((((1.96^2*0.5*0.5*($M11-N11))/(N11*($M11-1)))^0.5),"") -> 0.046117233
A12: Comunicación Social y Periodismo | B12: 27 | C12: 23 | D12: 32 | E12: 24 | F12: 33 | G12: 30 | H12: 31 | M12: 360 | N12: =SUM(B12:L12) -> 200 | O12: =N12/M12 -> 0.55555556 | P12: =IFERROR((((1.96^2*0.5*0.5*($M12-N12))/(N12*($M12-1)))^0.5),"") -> 0.04626194
A13: Ciencias Políticas | B13: 11 | C13: 10 | D13: 6 | E13: 17 | F13: 8 | G13: 9 | H13: 10 | M13: 85 | N13: =SUM(B13:L13) -> 71 | O13: =N13/M13 -> 0.83529412 | P13: =IFERROR((((1.96^2*0.5*0.5*($M13-N13))/(N13*($M13-1)))^0.5),"") -> 0.047481155
A14: Derecho | B14: 34 | C14: 16 | D14: 21 | E14: 20 | F14: 23 | G14: 20 | H14: 30 | I14: 19 | M14: 306 | N14: =SUM(B14:L14) -> 183 | O14: =N14/M14 -> 0.59803922 | P14: =IFERROR((((1.96^2*0.5*0.5*($M14-N14))/(N14*($M14-1)))^0.5),"") -> 0.046004802
A15: Licenciatura en Educación Infantil | B15: 15 | C15: 5 | D15: 5 | E15: 9 | F15: 12 | G15: 6 | H15: 8 | I15: 1 | J15: 0 | M15: 70 | N15: =SUM(B15:L15) -> 61 | O15: =N15/M15 -> 0.87142857 | P15: =IFERROR((((1.96^2*0.5*0.5*($M15-N15))/(N15*($M15-1)))^0.5),"") -> 0.045316657
A16: Enfermería | B16: 24 | C16: 16 | D16: 21 | E16: 14 | F16: 10 | G16: 14 | H16: 15 | M16: 150 | N16: =SUM(B16:L16) -> 114 | O16: =N16/M16 -> 0.76 | P16: =IFERROR((((1.96^2*0.5*0.5*($M16-N16))/(N16*($M16-1)))^0.5),"") -> 0.045116122
A17: Fisioterapia | B17: 20 | C17: 22 | D17: 33 | E17: 21 | F17: 18 | G17: 25 | H17: 11 | M17: 224 | N17: =SUM(B17:L17) -> 150 | O17: =N17/M17 -> 0.66964286 | P17: =IFERROR((((1.96^2*0.5*0.5*($M17-N17))/(N17*($M17-1)))^0.5),"") -> 0.046093944
A18: Filosofía | B18: 4 | C18: 3 | D18: 7 | E18: 6 | F18: 5 | G18: 1 | H18: 3 | I18: 5 | M18: 34 | N18: =SUM(B18:L18) -> 34 | O18: =N18/M18 -> 1 | P18: =IFERROR((((1.96^2*0.5*0.5*($M18-N18))/(N18*($M18-1)))^0.5),"") -> 0
A19: Ingeniería Civil | B19: 14 | C19: 8 | D19: 8 | E19: 14 | F19: 20 | G19: 8 | H19: 19 | M19: 114 | N19: =SUM(B19:L19) -> 91 | O19: =N19/M19 -> 0.79824561 | P19: =IFERROR((((1.96^2*0.5*0.5*($M19-N19))/(N19*($M19-1)))^0.5),"") -> 0.046347902
A20: Ingeniería Industrial | B20: 30 | C20: 19 | D20: 30 | E20: 12 | F20: 40 | G20: 20 | H20: 23 | M20: 287 | N20: =SUM(B20:L20) -> 174 | O20: =N20/M20 -> 0.60627178 | P20: =IFERROR((((1.96^2*0.5*0.5*($M20-N20))/(N20*($M20-1)))^0.5),"") -> 0.046699008
A21: Ingeniería Informática | B21: 39 | C21: 28 | D21: 37 | E21: 35 | F21: 16 | G21: 12 | H21: 22 | M21: 322 | N21: =SUM(B21:L21) -> 189 | O21: =N21/M21 -> 0.58695652 | P21: =IFERROR((((1.96^2*0.5*0.5*($M21-N21))/(N21*($M21-1)))^0.5),"") -> 0.045884761
A22: Ingeniería Mecánica | B22: 23 | C22: 19 | D22: 13 | E22: 9 | F22: 22 | G22: 15 | H22: 25 | M22: 175 | N22: =SUM(B22:L22) -> 126 | O22: =N22/M22 -> 0.72 | P22: =IFERROR((((1.96^2*0.5*0.5*($M22-N22))/(N22*($M22-1)))^0.5),"") -> 0.046330205
A23: Ingeniería de Bioproducción / Producción Agroindustrial | B23: 6 | C23: 2 | D23: 2 | E23: 6 | F23: 3 | G23: 1 | H23: 9 | I23: 4 | M23: 47 | N23: =SUM(B23:L23) -> 33 | O23: =N23/M23 -> 0.70212766 | P23: =IFERROR((((1.96^2*0.5*0.5*($M23-N23))/(N23*($M23-1)))^0.5),"") -> 0.094113995
A24: Ingeniería Química | B24: 15 | C24: 17 | D24: 19 | E24: 24 | F24: 18 | G24: 24 | H24: 20 | M24: 197 | N24: =SUM(B24:L24) -> 137 | O24: =N24/M24 -> 0.69543147 | P24: =IFERROR((((1.96^2*0.5*0.5*($M24-N24))/(N24*($M24-1)))^0.5),"") -> 0.046324782
A25: Medicina | B25: 43 | C25: 26 | D25: 23 | E25: 37 | F25: 31 | G25: 30 | H25: 33 | I25: 30 | J25: 22 | K25: 31 | M25: 972 | N25: =SUM(B25:K25) -> 306 | O25: =N25/M25 -> 0.31481481 | P25: =IFERROR((((1.96^2*0.5*0.5*($M25-N25))/(N25*($M25-1)))^0.5),"") -> 0.046397316
A26: Psicología | B26: 33 | C26: 22 | D26: 31 | E26: 29 | F26: 19 | G26: 30 | H26: 31 | M26: 340 | N26: =SUM(B26:L26) -> 195 | O26: =N26/M26 -> 0.57352941 | P26: =IFERROR((((1.96^2*0.5*0.5*($M26-N26))/(N26*($M26-1)))^0.5),"") -> 0.045897911
A27: Ciencia de Datos | B27: 21 | C27: 1 | D27: 1 | E27: 2 | F27: 0 | G27: 0 | H27: 0 | M27: 26 | N27: =SUM(B27:L27) -> 25 | O27: =N27/M27 -> 0.96153846 | P27: =IFERROR((((1.96^2*0.5*0.5*($M27-N27))/(N27*($M27-1)))^0.5),"") -> 0.0392
A28: Licenciatura en Ciencias Naturales | B28: 0 | C28: 3 | D28: 1 | E28: 3 | F28: 4 | G28: 0 | H28: 11 | I28: 6 | M28: 27 | N28: =SUM(B28:L28) -> 28 | O28: =N28/M28 -> 1.037037 | P28: =IFERROR((((1.96^2*0.5*0.5*($M28-N28))/(N28*($M28-1)))^0.5),"")
M29: =SUM(M4:M28) -> 6264 | N29: =SUM(N4:N28) -> 3504
A31: NOMBRE DEL PROGRAMA | B31: SEMESTRE 2 | C31: SEMESTRE 3 | D31: SEMESTRE 4 | E31: SEMESTRE 5 | F31: SEMESTRE 6 | G31: SEMESTRE 7 | H31: SEMESTRE 8 | I31: SEMESTRE 9 | J31: SEMESTRE 10 | K31: SEMESTRE 11 | L31: SEMESTRE 12 | M31: TOTAL POBLACIÓN
A32: Administración & Servicio | B32: =VLOOKUP($A32,'BDD Esudiantes'!$E$3:$P$30,2,0) -> 9 | C32: =VLOOKUP($A32,'BDD Esudiantes'!$E$3:$P$30,3,0) -> 11 | D32: =VLOOKUP($A32,'BDD Esudiantes'!$E$3:$P$30,4,0) -> 3 | E32: =VLOOKUP($A32,'BDD Esudiantes'!$E$3:$P$30,5,0) -> 7 | F32: =VLOOKUP($A32,'BDD Esudiantes'!$E$3:$P$30,6,0) -> 12 | G32: =VLOOKUP($A32,'BDD Esudiantes'!$E$3:$P$30,7,0) -> 12 | H32: =VLOOKUP($A32,'BDD Esudiantes'!$E$3:$P$30,8,0) -> 12 | M32: 82 | N32: =SUM(B32:L32) -> 66 | O32: =VLOOKUP($A32,'BDD Esudiantes'!$E$3:$P$30,12,0) -> 66 | P32: =O32-N32 -> 0 | Q32: =VLOOKUP(A32,'Resumen Estudiantes y Profesore'!$B$3:$F$27,5,0) -> 66 | R32: =Q32-O32 -> 0
A33: Administración de Empresas | B33: =VLOOKUP($A33,'BDD Esudiantes'!$E$3:$P$30,2,0) -> 23 | C33: =VLOOKUP($A33,'BDD Esudiantes'!$E$3:$P$30,3,0) -> 12 | D33: =VLOOKUP($A33,'BDD Esudiantes'!$E$3:$P$30,4,0) -> 22 | E33: =VLOOKUP($A33,'BDD Esudiantes'!$E$3:$P$30,5,0) -> 18 | F33: =VLOOKUP($A33,'BDD Esudiantes'!$E$3:$P$30,6,0) -> 23 | G33: =VLOOKUP($A33,'BDD Esudiantes'!$E$3:$P$30,7,0) -> 19 | H33: =VLOOKUP($A33,'BDD Esudiantes'!$E$3:$P$30,8,0) -> 30 | M33: 253 | N33: =SUM(B33:L33) -> 147 | O33: =VLOOKUP($A33,'BDD Esudiantes'!$E$3:$P$30,12,0) -> 147 | P33: =O33-N33 -> 0 | Q33: =VLOOKUP(A33,'Resumen Estudiantes y Profesore'!$B$3:$F$27,5,0) -> 147 | R33: =Q33-O33 -> 0
A34: Administración de Mercadeo y Logística Internacionales | B34: =VLOOKUP($A34,'BDD Esudiantes'!$E$3:$P$30,2,0) -> 2 | C34: =VLOOKUP($A34,'BDD Esudiantes'!$E$3:$P$30,3,0) -> 29 | D34: =VLOOKUP($A34,'BDD Esudiantes'!$E$3:$P$30,4,0) -> 47 | E34: =VLOOKUP($A34,'BDD Esudiantes'!$E$3:$P$30,5,0) -> 35 | F34: =VLOOKUP($A34,'BDD Esudiantes'!$E$3:$P$30,6,0) -> 53 | G34: =VLOOKUP($A34,'BDD Esudiantes'!$E$3:$P$30,7,0) -> 29 | H34: =VLOOKUP($A34,'BDD Esudiantes'!$E$3:$P$30,8,0) -> 28 | M34: 356 | N34: =SUM(B34:L34) -> 223 | O34: =VLOOKUP($A34,'BDD Esudiantes'!$E$3:$P$30,12,0) -> 223 | P34: =O34-N34 -> 0 | Q34: =VLOOKUP(A34,'Resumen Estudiantes y Profesore'!$B$3:$F$27,5,0) -> 223 | R34: =Q34-O34 -> 0
A35: Administración de Negocios Internacionales | B35: =VLOOKUP($A35,'BDD Esudiantes'!$E$3:$P$30,2,0) -> 48 | C35: =VLOOKUP($A35,'BDD Esudiantes'!$E$3:$P$30,3,0) -> 50 | D35: =VLOOKUP($A35,'BDD Esudiantes'!$E$3:$P$30,4,0) -> 65 | E35: =VLOOKUP($A35,'BDD Esudiantes'!$E$3:$P$30,5,0) -> 48 | F35: =VLOOKUP($A35,'BDD Esudiantes'!$E$3:$P$30,6,0) -> 28 | G35: =VLOOKUP($A35,'BDD Esudiantes'!$E$3:$P$30,7,0) -> 29 | H35: =VLOOKUP($A35,'BDD Esudiantes'!$E$3:$P$30,8,0) -> 31 | M35: 582 | N35: =SUM(B35:L35) -> 299 | O35: =VLOOKUP($A35,'BDD Esudiantes'!$E$3:$P$30,12,0) -> 299 | P35: =O35-N35 -> 0 | Q35: =VLOOKUP(A35,'Resumen Estudiantes y Profesore'!$B$3:$F$27,5,0) -> 299 | R35: =Q35-O35 -> 0
A36: Economía y Finanzas Internacionales | B36: =VLOOKUP($A36,'BDD Esudiantes'!$E$3:$P$30,2,0) -> 27 | C36: =VLOOKUP($A36,'BDD Esudiantes'!$E$3:$P$30,3,0) -> 17 | D36: =VLOOKUP($A36,'BDD Esudiantes'!$E$3:$P$30,4,0) -> 34 | E36: =VLOOKUP($A36,'BDD Esudiantes'!$E$3:$P$30,5,0) -> 14 | F36: =VLOOKUP($A36,'BDD Esudiantes'!$E$3:$P$30,6,0) -> 23 | G36: =VLOOKUP($A36,'BDD Esudiantes'!$E$3:$P$30,7,0) -> 13 | H36: =VLOOKUP($A36,'BDD Esudiantes'!$E$3:$P$30,8,0) -> 13 | M36: 209 | N36: =SUM(B36:L36) -> 141 | O36: =VLOOKUP($A36,'BDD Esudiantes'!$E$3:$P$30,12,0) -> 141 | P36: =O36-N36 -> 0 | Q36: =VLOOKUP(A36,'Resumen Estudiantes y Profesore'!$B$3:$F$27,5,0) -> 141 | R36: =Q36-O36 -> 0
A37: Gastronomía | B37: =VLOOKUP($A37,'BDD Esudiantes'!$E$3:$P$30,2,0) -> 31 | C37: =VLOOKUP($A37,'BDD Esudiantes'!$E$3:$P$30,3,0) -> 17 | D37: =VLOOKUP($A37,'BDD Esudiantes'!$E$3:$P$30,4,0) -> 25 | E37: =VLOOKUP($A37,'BDD Esudiantes'!$E$3:$P$30,5,0) -> 16 | F37: =VLOOKUP($A37,'BDD Esudiantes'!$E$3:$P$30,6,0) -> 23 | G37: =VLOOKUP($A37,'BDD Esudiantes'!$E$3:$P$30,7,0) -> 12 | H37: =VLOOKUP($A37,'BDD Esudiantes'!$E$3:$P$30,8,0) -> 7 | M37: 234 | N37: =SUM(B37:L37) -> 131 | O37: =VLOOKUP($A37,'BDD Esudiantes'!$E$3:$P$30,12,0) -> 131 | P37: =O37-N37 -> 0 | Q37: =VLOOKUP(A37,'Resumen Estudiantes y Profesore'!$B$3:$F$27,5,0) -> 131 | R37: =Q37-O37 -> 0
A38: Comunicación Corporativa | B38: =VLOOKUP($A38,'BDD Esudiantes'!$E$3:$P$30,2,0) -> 12 | C38: =VLOOKUP($A38,'BDD Esudiantes'!$E$3:$P$30,3,0) -> 26 | D38: =VLOOKUP($A38,'BDD Esudiantes'!$E$3:$P$30,4,0) -> 7 | E38: =VLOOKUP($A38,'BDD Esudiantes'!$E$3:$P$30,5,0) -> 16 | F38: =VLOOKUP($A38,'BDD Esudiantes'!$E$3:$P$30,6,0) -> 22 | G38: =VLOOKUP($A38,'BDD Esudiantes'!$E$3:$P$30,7,0) -> 15 | H38: =VLOOKUP($A38,'BDD Esudiantes'!$E$3:$P$30,8,0) -> 14 | M38: 195 | N38: =SUM(B38:L38) -> 112 | O38: =VLOOKUP($A38,'BDD Esudiantes'!$E$3:$P$30,12,0) -> 112 | P38: =O38-N38 -> 0 | Q38: =VLOOKUP(A38,'Resumen Estudiantes y Profesore'!$B$3:$F$27,5,0) -> 112 | R38: =Q38-O38 -> 0
A39: Comunicación Audiovisual y Multimedios | B39: =VLOOKUP($A39,'BDD Esudiantes'!$E$3:$P$30,2,0) -> 56 | C39: =VLOOKUP($A39,'BDD Esudiantes'!$E$3:$P$30,3,0) -> 35 | D39: =VLOOKUP($A39,'BDD Esudiantes'!$E$3:$P$30,4,0) -> 69 | E39: =VLOOKUP($A39,'BDD Esudiantes'!$E$3:$P$30,5,0) -> 35 | F39: =VLOOKUP($A39,'BDD Esudiantes'!$E$3:$P$30,6,0) -> 21 | G39: =VLOOKUP($A39,'BDD Esudiantes'!$E$3:$P$30,7,0) -> 18 | H39: =VLOOKUP($A39,'BDD Esudiantes'!$E$3:$P$30,8,0) -> 33 | M39: 606 | N39: =SUM(B39:L39) -> 267 | O39: =VLOOKUP($A39,'BDD Esudiantes'!$E$3:$P$30,12,0) -> 267 | P39: =O39-N39 -> 0 | Q39: =VLOOKUP(A39,'Resumen Estudiantes y Profesore'!$B$3:$F$27,5,0) -> 267 | R39: =Q39-O39 -> 0
A40: Comunicación Social y Periodismo | B40: =VLOOKUP($A40,'BDD Esudiantes'!$E$3:$P$30,2,0) -> 30 | C40: =VLOOKUP($A40,'BDD Esudiantes'!$E$3:$P$30,3,0) -> 31 | D40: =VLOOKUP($A40,'BDD Esudiantes'!$E$3:$P$30,4,0) -> 45 | E40: =VLOOKUP($A40,'BDD Esudiantes'!$E$3:$P$30,5,0) -> 25 | F40: =VLOOKUP($A40,'BDD Esudiantes'!$E$3:$P$30,6,0) -> 34 | G40: =VLOOKUP($A40,'BDD Esudiantes'!$E$3:$P$30,7,0) -> 17 | H40: =VLOOKUP($A40,'BDD Esudiantes'!$E$3:$P$30,8,0) -> 14 | M40: 375 | N40: =SUM(B40:L40) -> 196 | O40: =VLOOKUP($A40,'BDD Esudiantes'!$E$3:$P$30,12,0) -> 196 | P40: =O40-N40 -> 0 | Q40: =VLOOKUP(A40,'Resumen Estudiantes y Profesore'!$B$3:$F$27,5,0) -> 196 | R40: =Q40-O40 -> 0
A41: Ciencias Políticas | B41: =VLOOKUP($A41,'BDD Esudiantes'!$E$3:$P$30,2,0) -> 7 | C41: =VLOOKUP($A41,'BDD Esudiantes'!$E$3:$P$30,3,0) -> 12 | D41: =VLOOKUP($A41,'BDD Esudiantes'!$E$3:$P$30,4,0) -> 11 | E41: =VLOOKUP($A41,'BDD Esudiantes'!$E$3:$P$30,5,0) -> 6 | F41: =VLOOKUP($A41,'BDD Esudiantes'!$E$3:$P$30,6,0) -> 13 | G41: =VLOOKUP($A41,'BDD Esudiantes'!$E$3:$P$30,7,0) -> 8 | H41: =VLOOKUP($A41,'BDD Esudiantes'!$E$3:$P$30,8,0) -> 11 | M41: 85 | N41: =SUM(B41:L41) -> 68 | O41: =VLOOKUP($A41,'BDD Esudiantes'!$E$3:$P$30,12,0) -> 68 | P41: =O41-N41 -> 0 | Q41: =VLOOKUP(A41,'Resumen Estudiantes y Profesore'!$B$3:$F$27,5,0) -> 68 | R41: =Q41-O41 -> 0
A42: Derecho | B42: =VLOOKUP($A42,'BDD Esudiantes'!$E$3:$P$30,2,0) -> 49 | C42: =VLOOKUP($A42,'BDD Esudiantes'!$E$3:$P$30,3,0) -> 14 | D42: =VLOOKUP($A42,'BDD Esudiantes'!$E$3:$P$30,4,0) -> 23 | E42: =VLOOKUP($A42,'BDD Esudiantes'!$E$3:$P$30,5,0) -> 16 | F42: =VLOOKUP($A42,'BDD Esudiantes'!$E$3:$P$30,6,0) -> 32 | G42: =VLOOKUP($A42,'BDD Esudiantes'!$E$3:$P$30,7,0) -> 21 | H42: =VLOOKUP($A42,'BDD Esudiantes'!$E$3:$P$30,8,0) -> 19 | I42: =VLOOKUP($A42,'BDD Esudiantes'!$E$3:$P$30,9,0) -> 16 | M42: 247 | N42: =SUM(B42:L42) -> 190 | O42: =VLOOKUP($A42,'BDD Esudiantes'!$E$3:$P$30,12,0) -> 190 | P42: =O42-N42 -> 0 | Q42: =VLOOKUP(A42,'Resumen Estudiantes y Profesore'!$B$3:$F$27,5,0) -> 190 | R42: =Q42-O42 -> 0
...

Sheet BDD Esudiantes
A1: F3 | B1: Semestre | C1: Nombre de Programa | E1: Cuenta de Nombre de Programa | F1: Etiquetas de columna
A2: 39 | B2: 6 | C2: =VLOOKUP(A2,'Programas y Unidades'!$A:$B,2,0) -> Ingeniería Informática | E2: Etiquetas de fila | F2: 2 | G2: 3 | H2: 4 | I2: 5 | J2: 6 | K2: 7 | L2: 8 | M2: 9 | N2: 10 | O2: 11 | P2: Total general
A3: 39 | B3: 6 | C3: =VLOOKUP(A3,'Programas y Unidades'!$A:$B,2,0) -> Ingeniería Informática | E3: Administración & Servicio | F3: 9 | G3: 11 | H3: 3 | I3: 7 | J3: 12 | K3: 12 | L3: 12 | P3: 66
A4: 39 | B4: 7 | C4: =VLOOKUP(A4,'Programas y Unidades'!$A:$B,2,0) -> Ingeniería Informática | E4: Administración de Empresas | F4: 23 | G4: 12 | H4: 22 | I4: 18 | J4: 23 | K4: 19 | L4: 30 | P4: 147
A5: 39 | B5: 6 | C5: =VLOOKUP(A5,'Programas y Unidades'!$A:$B,2,0) -> Ingeniería Informática | E5: Administración de Mercadeo y Logística Internacionales | F5: 2 | G5: 29 | H5: 47 | I5: 35 | J5: 53 | K5: 29 | L5: 28 | P5: 223
A6: 39 | B6: 6 | C6: =VLOOKUP(A6,'Programas y Unidades'!$A:$B,2,0) -> Ingeniería Informática | E6: Administración de Negocios Internacionales | F6: 48 | G6: 50 | H6: 65 | I6: 48 | J6: 28 | K6: 29 | L6: 31 | P6: 299
A7: 39 | B7: 6 | C7: =VLOOKUP(A7,'Programas y Unidades'!$A:$B,2,0) -> Ingeniería Informática | E7: Comunicación Audiovisual y Multimedios | F7: 56 | G7: 35 | H7: 69 | I7: 35 | J7: 21 | K7: 18 | L7: 33 | P7: 267
A8: 39 | B8: 7 | C8: =VLOOKUP(A8,'Programas y Unidades'!$A:$B,2,0) -> Ingeniería Informática | E8: Comunicación Corporativa | F8: 12 | G8: 26 | H8: 7 | I8: 16 | J8: 22 | K8: 15 | L8: 14 | P8: 112
A9: 39 | B9: 5 | C9: =VLOOKUP(A9,'Programas y Unidades'!$A:$B,2,0) -> Ingeniería Informática | E9: Comunicación Social y Periodismo | F9: 30 | G9: 31 | H9: 45 | I9: 25 | J9: 34 | K9: 17 | L9: 14 | P9: 196
A10: 39 | B10: 5 | C10: =VLOOKUP(A10,'Programas y Unidades'!$A:$B,2,0) -> Ingeniería Informática | E10: Economía y Finanzas Internacionales | F10: 27 | G10: 17 | H10: 34 | I10: 14 | J10: 23 | K10: 13 | L10: 13 | P10: 141
A11: 39 | B11: 5 | C11: =VLOOKUP(A11,'Programas y Unidades'!$A:$B,2,0) -> Ingeniería Informática | E11: Fisioterapia | F11: 21 | G11: 1 | H11: 37 | I11: 43 | J11: 28 | K11: 19 | L11: 33 | P11: 182
A12: 39 | B12: 6 | C12: =VLOOKUP(A12,'Programas y Unidades'!$A:$B,2,0) -> Ingeniería Informática | E12: Gastronomía | F12: 31 | G12: 17 | H12: 25 | I12: 16 | J12: 23 | K12: 12 | L12: 7 | P12: 131
A13: 39 | B13: 7 | C13: =VLOOKUP(A13,'Programas y Unidades'!$A:$B,2,0) -> Ingeniería Informática | E13: Ingeniería Civil | F13: 17 | G13: 9 | H13: 12 | I13: 11 | J13: 21 | K13: 8 | L13: 23 | P13: 101
A14: 39 | B14: 7 | C14: =VLOOKUP(A14,'Programas y Unidades'!$A:$B,2,0) -> Ingeniería Informática | E14: Ingeniería Industrial | F14: 34 | G14: 22 | H14: 28 | I14: 9 | J14: 49 | K14: 23 | L14: 20 | P14: 185
... A17: 39 | B17: 6 | C17: =VLOOKUP(A17,'Programas y Unidades'!$A:$B,2,0) -> Ingeniería Informática | E17: Ingeniería Química | F17: 24 | G17: 17 | H17: 19 | I17: 18 | J17: 17 | K17: 20 | L17: 24 | P17: 139
A18: 39 | B18: 5 | C18: =VLOOKUP(A18,'Programas y Unidades'!$A:$B,2,0) -> Ingeniería Informática | E18: Licenciatura en Ciencias Naturales | H18: 2 | I18: 1 | J18: 1 | L18: 5 | M18: 2 | P18: 11
A19: 39 | B19: 7 | C19: =VLOOKUP(A19,'Programas y Unidades'!$A:$B,2,0) -> Ingeniería Informática | E19: Licenciatura en Educación Infantil | F19: 14 | G19: 5 | H19: 6 | I19: 9 | J19: 2 | K19: 4 | L19: 9 | M19: 2 | N19: 3 | P19: 54
A20: 39 | B20: 5 | C20: =VLOOKUP(A20,'Programas y Unidades'!$A:$B,2,0) -> Ingeniería Informática | E20: Psicología | F20: 49 | G20: 26 | H20: 37 | I20: 27 | J20: 18 | K20: 14 | L20: 32 | P20: 203
A21: 39 | B21: 6 | C21: =VLOOKUP(A21,'Programas y Unidades'!$A:$B,2,0) -> Ingeniería Informática | E21: Ciencia de Datos | F21: 19 | G21: 3 | I21: 2 | P21: 24
A22: 39 | B22: 6 | C22: =VLOOKUP(A22,'Programas y Unidades'!$A:$B,2,0) -> Ingeniería Informática | E22: Derecho | F22: 49 | G22: 14 | H22: 23 | I22: 16 | J22: 32 | K22: 21 | L22: 19 | M22: 16 | P22: 190
A23: 39 | B23: 5 | C23: =VLOOKUP(A23,'Programas y Unidades'!$A:$B,2,0) -> Ingeniería Informática | E23: Enfermería | F23: 27 | G23: 19 | H23: 25 | I23: 14 | J23: 16 | K23: 12 | L23: 19 | P23: 132
A24: 39 | B24: 6 | C24: =VLOOKUP(A24,'Programas y Unidades'!$A:$B,2,0) -> Ingeniería Informática | E24: Ingeniería de Producción Agroindustrial | F24: 2 | K24: 1 | L24: 10 | P24: 13
A25: 39 | B25: 5 | C25: =VLOOKUP(A25,'Programas y Unidades'!$A:$B,2,0) -> Ingeniería Informática | E25: Ingeniería de Bioproducción | F25: 5 | H25: 3 | I25: 7 | J25: 2 | K25: 2 | L25: 3 | P25: 22
A26: 39 | B26: 6 | C26: =VLOOKUP(A26,'Programas y Unidades'!$A:$B,2,0) -> Ingeniería Informática | E26: Ciencias Políticas | F26: 7 | G26: 12 | H26: 11 | I26: 6 | J26: 13 | K26: 8 | L26: 11 | P26: 68
A27: 39 | B27: 5 | C27: =VLOOKUP(A27,'Programas y Unidades'!$A:$B,2,0) -> Ingeniería Informática | E27: Filosofía | F27: 5 | G27: 1 | H27: 6 | I27: 5 | J27: 7 | K27: 1 | L27: 2 | M27: 4 | P27: 31
A28: 39 | B28: 5 | C28: =VLOOKUP(A28,'Programas y Unidades'!$A:$B,2,0) -> Ingeniería Informática | E28: Medicina | F28: 82 | G28: 69 | H28: 62 | I28: 108 | J28: 58 | K28: 54 | L28: 55 | M28: 54 | N28: 49 | O28: 88 | P28: 679
A29: 39 | B29: 6 | C29: =VLOOKUP(A29,'Programas y Unidades'!$A:$B,2,0) -> Ingeniería Informática | E29: Total general | F29: 638 | G29: 472 | H29: 639 | I29: 540 | J29: 567 | K29: 381 | L29: 506 | M29: 78 | N29: 52 | O29: 88 | P29: 3961
A30: 39 | B30: 5 | C30: =VLOOKUP(A30,'Programas y Unidades'!$A:$B,2,0) -> Ingeniería Informática
A31: 39 | B31: 8 | C31: =VLOOKUP(A31,'Programas y Unidades'!$A:$B,2,0) -> Ingeniería Informática
A32: 148 | B32: 2 | C32: =VLOOKUP(A32,'Programas y Unidades'!$A:$B,2,0) -> Ciencia de Datos
A33: 39 | B33: 7 | C33: =VLOOKUP(A33,'Programas y Unidades'!$A:$B,2,0) -> Ingeniería Informática
A34: 40 | B34: 5 | C34: =VLOOKUP(A34,'Programas y Unidades'!$A:$B,2,0) -> Ingeniería Mecánica
A35: 39 | B35: 6 | C35: =VLOOKUP(A35,'Programas y Unidades'!$A:$B,2,0) -> Ingeniería Informática
A36: 148 | B36: 3 | C36: =VLOOKUP(A36,'Programas y Unidades'!$A:$B,2,0) -> Ciencia de Datos
A37: 148 | B37: 2 | C37: =VLOOKUP(A37,'Programas y Unidades'!$A:$B,2,0) -> Ciencia de Datos
A38: 148 | B38: 5 | C38: =VLOOKUP(A38,'Programas y Unidades'!$A:$B,2,0) -> Ciencia de Datos
A39: 148 | B39: 5 | C39: =VLOOKUP(A39,'Programas y Unidades'!$A:$B,2,0) -> Ciencia de Datos
A40: 32 | B40: 8 | C40: =VLOOKUP(A40,'Programas y Unidades'!$A:$B,2,0) -> Licenciatura en Educación Infantil
A41: 32 | B41: 8 | C41: =VLOOKUP(A41,'Programas y Unidades'!$A:$B,2,0) -> Licenciatura en Educación Infantil
... A5724: 86 | B5724: 4 | C5724: =VLOOKUP(A5724,'Programas y Unidades'!$A:$B,2,0) -> Maestría en Didáctica Del Inglés Para el Aprendizaje Autodirigido - Virtual

Sheet Resumen Estudiantes y Profesore
D1: ESTUDIANTES | L1: PROFESOR PLANTA | T1: PROFESOR CATEDRA
A2: COD | B2: PROGRAMA | C2: UNIDAD | D2: Universo | E2: Muestra (ME 5 % NC 95%) | F2: Realizado | G2: Faltantes | H2: Alcance Vs Población | I2: ME (NC 95%) | J2: ME (NC 90%) | K2: Tipo de medición | L2: Universo | M2: Muestra (ME 5 % NC 95%) | N2: Realizado | O2: Faltantes | P2: Alcance Vs Población | Q2: ME (NC 95%) | R2: ME (NC 90%) | S2: Tipo de medición | T2: Universo | U2: Muestra (ME 5 % NC 95%) | V2: Realizado | W2: Faltantes | X2: Alcance Vs Población | Y2: ME (NC 95%) | Z2: ME (NC 90%) | AA2: Tipo de medición
A3: 20 | B3: Administración & Servicio | C3: ESCUELA INTERNACIONAL DE CIENCIAS ECONÓMICAS Y ADMINISTRATIVAS | D3: =VLOOKUP(B3,'Cuotas Estudiantes Pregrado'!$A$4:$N$28,13,0) -> 84 | E3: =VLOOKUP(B3,'Cuotas Estudiantes Pregrado'!$A$4:$N$28,14,0) -> 71 | F3: =VLOOKUP(B3,'BDD Estudiantes Posgrado'!$A$1:$D$200,4,0) -> 66 | G3: =VLOOKUP(B3,'Cuotas Estudiantes Pregrado'!$A$117:$M$142,13,0) -> 7 | H3: =F3/D3 -> 0.78571429 | I3: =IFERROR((((1.96^2*0.5*0.5*($D3-F3))/(F3*($D3-1)))^0.5),"") -> 0.056176065 | J3: =IFERROR((((1.65^2*0.5*0.5*($D3-F3))/(F3*($D3-1)))^0.5),"") -> 0.047291075 | K3: Encuesta | L3: ='BDD Prof. Planta'!$H$10 -> 40 | M3: 40 | N3: ='BDD Prof. Planta'!$D$10 -> 40 | O3: =M3-N3 -> 0 | P3: =N3/L3 -> 1 | Q3: =IFERROR((((1.96^2*0.5*0.5*($L3-N3))/(N3*($L3-1)))^0.5),"") -> 0 | R3: =IFERROR((((1.65^2*0.5*0.5*($L3-N3))/(N3*($L3-1)))^0.5),"") -> 0 | S3: Encuesta | T3: ='BDD Prof. Catedra'!$H$10 -> 112 | U3: 92 | V3: ='BDD Prof. Catedra'!$D$10 -> 90 | W3: =U3-V3 -> 2 | X3: =V3/T3 -> 0.80357143 | Y3: =IFERROR((((1.96^2*0.5*0.5*($T3-V3))/(V3*($T3-1)))^0.5),"") -> 0.045989075 | Z3: =IFERROR((((1.65^2*0.5*0.5*($T3-V3))/(V3*($T3-1)))^0.5),"") -> 0.038715293 | AA3: Encuesta
A4: 21 | B4: Administración de Empresas | C4: ESCUELA INTERNACIONAL DE CIENCIAS ECONÓMICAS Y ADMINISTRATIVAS | D4: =VLOOKUP(B4,'Cuotas Estudiantes Pregrado'!$A$4:$N$28,13,0) -> 253 | E4: =VLOOKUP(B4,'Cuotas Estudiantes Pregrado'!$A$4:$N$28,14,0) -> 162 | F4: =VLOOKUP(B4,'BDD Estudiantes Posgrado'!$A$1:$D$200,4,0) -> 147 | G4: =VLOOKUP(B4,'Cuotas Estudiantes Pregrado'!$A$117:$M$142,13,0) -> 21 | H4: =F4/D4 -> 0.58102767 | I4: =IFERROR((((1.96^2*0.5*0.5*($D4-F4))/(F4*($D4-1)))^0.5),"") -> 0.052422783 | J4: =IFERROR((((1.65^2*0.5*0.5*($D4-F4))/(F4*($D4-1)))^0.5),"") -> 0.044131424 | K4: Encuesta | L4: ='BDD Prof. Planta'!$H$10 -> 40 | M4: 40 | N4: ='BDD Prof. Planta'!$D$10 -> 40 | O4: =M4-N4 -> 0 | P4: =N4/L4 -> 1 | Q4: =IFERROR((((1.96^2*0.5*0.5*($L4-N4))/(N4*($L4-1)))^0.5),"") -> 0 | R4: =IFERROR((((1.65^2*0.5*0.5*($L4-N4))/(N4*($L4-1)))^0.5),"") -> 0 | S4: Encuesta | T4: ='BDD Prof. Catedra'!$H$10 -> 112 | U4: 92 | V4: ='BDD Prof. Catedra'!$D$10 -> 90 | W4: =U4-V4 -> 2 | X4: =V4/T4 -> 0.80357143 | Y4: =IFERROR((((1.96^2*0.5*0.5*($T4-V4))/(V4*($T4-1)))^0.5),"") -> 0.045989075 | Z4: =IFERROR((((1.65^2*0.5*0.5*($T4-V4))/(V4*($T4-1)))^0.5),"") -> 0.038715293 | AA4: Encuesta | AD4: Encuestas (ME <= 7,0% a NC 90%)
A5: 22 | B5: Administración de Mercadeo y Logística Internacionales | C5: ESCUELA INTERNACIONAL DE CIENCIAS ECONÓMICAS Y ADMINISTRATIVAS | D5: =VLOOKUP(B5,'Cuotas Estudiantes Pregrado'!$A$4:$N$28,13,0) -> 344 | E5: =VLOOKUP(B5,'Cuotas Estudiantes Pregrado'!$A$4:$N$28,14,0) -> 195 | F5: =VLOOKUP(B5,'BDD Estudiantes Posgrado'!$A$1:$D$200,4,0) -> 223 | G5: =VLOOKUP(B5,'Cuotas Estudiantes Pregrado'!$A$117:$M$142,13,0) -> 32 | H5: =F5/D5 -> 0.64825581 | I5: =IFERROR((((1.96^2*0.5*0.5*($D5-F5))/(F5*($D5-1)))^0.5),"") -> 0.038977975 | J5: =IFERROR((((1.65^2*0.5*0.5*($D5-F5))/(F5*($D5-1)))^0.5),"") -> 0.032813091 | K5: Encuesta | L5: ='BDD Prof. Planta'!$H$10 -> 40 | M5: 40 | N5: ='BDD Prof. Planta'!$D$10 -> 40 | O5: =M5-N5 -> 0 | P5: =N5/L5 -> 1 | Q5: =IFERROR((((1.96^2*0.5*0.5*($L5-N5))/(N5*($L5-1)))^0.5),"") -> 0 | R5: =IFERROR((((1.65^2*0.5*0.5*($L5-N5))/(N5*($L5-1)))^0.5),"") -> 0 | S5: Encuesta | T5: ='BDD Prof. Catedra'!$H$10 -> 112 | U5: 92 | V5: ='BDD Prof. Catedra'!$D$10 -> 90 | W5: =U5-V5 -> 2 | X5: =V5/T5 -> 0.80357143 | Y5: =IFERROR((((1.96^2*0.5*0.5*($T5-V5))/(V5*($T5-1)))^0.5),"") -> 0.045989075 | Z5: =IFERROR((((1.65^2*0.5*0.5*($T5-V5))/(V5*($T5-1)))^0.5),"") -> 0.038715293 | AA5: Encuesta | AD5: Encuestas (ME > 7,0% a NC 90% y Alcance >= 80%)
A6: 23 | B6: Administración de Negocios Internacionales | C6: ESCUELA INTERNACIONAL DE CIENCIAS ECONÓMICAS Y ADMINISTRATIVAS | D6: =VLOOKUP(B6,'Cuotas Estudiantes Pregrado'!$A$4:$N$28,13,0) -> 580 | E6: =VLOOKUP(B6,'Cuotas Estudiantes Pregrado'!$A$4:$N$28,14,0) -> 254 | F6: =VLOOKUP(B6,'BDD Estudiantes Posgrado'!$A$1:$D$200,4,0) -> 299 | G6: =VLOOKUP(B6,'Cuotas Estudiantes Pregrado'!$A$117:$M$142,13,0) -> 13 | H6: =F6/D6 -> 0.51551724 | I6: =IFERROR((((1.96^2*0.5*0.5*($D6-F6))/(F6*($D6-1)))^0.5),"") -> 0.039482474 | J6: =IFERROR((((1.65^2*0.5*0.5*($D6-F6))/(F6*($D6-1)))^0.5),"") -> 0.033237797 | K6: Encuesta | L6: ='BDD Prof. Planta'!$H$10 -> 40 | M6: 40 | N6: ='BDD Prof. Planta'!$D$10 -> 40 | O6: =M6-N6 -> 0 | P6: =N6/L6 -> 1 | Q6: =IFERROR((((1.96^2*0.5*0.5*($L6-N6))/(N6*($L6-1)))^0.5),"") -> 0 | R6: =IFERROR((((1.65^2*0.5*0.5*($L6-N6))/(N6*($L6-1)))^0.5),"") -> 0 | S6: Encuesta | T6: ='BDD Prof. Catedra'!$H$10 -> 112 | U6: 92 | V6: ='BDD Prof. Catedra'!$D$10 -> 90 | W6: =U6-V6 -> 2 | X6: =V6/T6 -> 0.80357143 | Y6: =IFERROR((((1.96^2*0.5*0.5*($T6-V6))/(V6*($T6-1)))^0.5),"") -> 0.045989075 | Z6: =IFERROR((((1.65^2*0.5*0.5*($T6-V6))/(V6*($T6-1)))^0.5),"") -> 0.038715293 | AA6: Encuesta | AD6: Sondeo (ME > 7,0% a NC 90% y Alcance < 80%)
A7: 24 | B7: Economía y Finanzas Internacionales | C7: ESCUELA INTERNACIONAL DE CIENCIAS ECONÓMICAS Y ADMINISTRATIVAS | D7: =VLOOKUP(B7,'Cuotas Estudiantes Pregrado'!$A$4:$N$28,13,0) -> 215 | E7: =VLOOKUP(B7,'Cuotas Estudiantes Pregrado'!$A$4:$N$28,14,0) -> 146 | F7: =VLOOKUP(B7,'BDD Estudiantes Posgrado'!$A$1:$D$200,4,0) -> 141 | G7: =VLOOKUP(B7,'Cuotas Estudiantes Pregrado'!$A$117:$M$142,13,0) -> 26 | H7: =F7/D7 -> 0.65581395 | I7: =IFERROR((((1.96^2*0.5*0.5*($D7-F7))/(F7*($D7-1)))^0.5),"") -> 0.048531699 | J7: =IFERROR((((1.65^2*0.5*0.5*($D7-F7))/(F7*($D7-1)))^0.5),"") -> 0.040855767 | K7: Encuesta | L7: ='BDD Prof. Planta'!$H$10 -> 40 | M7: 40 | N7: ='BDD Prof. Planta'!$D$10 -> 40 | O7: =M7-N7 -> 0 | P7: =N7/L7 -> 1 | Q7: =IFERROR((((1.96^2*0.5*0.5*($L7-N7))/(N7*($L7-1)))^0.5),"") -> 0 | R7: =IFERROR((((1.65^2*0.5*0.5*($L7-N7))/(N7*($L7-1)))^0.5),"") -> 0 | S7: Encuesta | T7: ='BDD Prof. Catedra'!$H$10 -> 112 | U7: 92 | V7: ='BDD Prof. Catedra'!$D$10 -> 90 | W7: =U7-V7 -> 2 | X7: =V7/T7 -> 0.80357143 | Y7: =IFERROR((((1.96^2*0.5*0.5*($T7-V7))/(V7*($T7-1)))^0.5),"") -> 0.045989075 | Z7: =IFERROR((((1.65^2*0.5*0.5*($T7-V7))/(V7*($T7-1)))^0.5),"") -> 0.038715293 | AA7: Encuesta | AD7: Sin información / Sin respuestas
A8: 25 | B8: Gastronomía | C8: ESCUELA INTERNACIONAL DE CIENCIAS ECONÓMICAS Y ADMINISTRATIVAS | D8: =VLOOKUP(B8,'Cuotas Estudiantes Pregrado'!$A$4:$N$28,13,0) -> 240 | E8: =VLOOKUP(B8,'Cuotas Estudiantes Pregrado'!$A$4:$N$28,14,0) -> 158 | F8: =VLOOKUP(B8,'BDD Estudiantes Posgrado'!$A$1:$D$200,4,0) -> 131 | G8: =VLOOKUP(B8,'Cuotas Estudiantes Pregrado'!$A$117:$M$142,13,0) -> 32 | H8: =F8/D8 -> 0.54583333 | I8: =IFERROR((((1.96^2*0.5*0.5*($D8-F8))/(F8*($D8-1)))^0.5),"") -> 0.057823547 | J8: =IFERROR((((1.65^2*0.5*0.5*($D8-F8))/(F8*($D8-1)))^0.5),"") -> 0.048677986 | K8: Encuesta | L8: ='BDD Prof. Planta'!$H$10 -> 40 | M8: 40 | N8: ='BDD Prof. Planta'!$D$10 -> 40 | O8: =M8-N8 -> 0 | P8: =N8/L8 -> 1 | Q8: =IFERROR((((1.96^2*0.5*0.5*($L8-N8))/(N8*($L8-1)))^0.5),"") -> 0 | R8: =IFERROR((((1.65^2*0.5*0.5*($L8-N8))/(N8*($L8-1)))^0.5),"") -> 0 | S8: Encuesta | T8: ='BDD Prof. Catedra'!$H$10 -> 112 | U8: 92 | V8: ='BDD Prof. Catedra'!$D$10 -> 90 | W8: =U8-V8 -> 2 | X8: =V8/T8 -> 0.80357143 | Y8: =IFERROR((((1.96^2*0.5*0.5*($T8-V8))/(V8*($T8-1)))^0.5),"") -> 0.045989075 | Z8: =IFERROR((((1.65^2*0.5*0.5*($T8-V8))/(V8*($T8-1)))^0.5),"") -> 0.038715293 | AA8: Encuesta
A9: 26 | B9: Comunicación Corporativa | C9: FACULTAD DE COMUNICACIÓN | D9: =VLOOKUP(B9,'Cuotas Estudiantes Pregrado'!$A$4:$N$28,13,0) -> 206 | E9: =VLOOKUP(B9,'Cuotas Estudiantes Pregrado'!$A$4:$N$28,14,0) -> 142 | F9: =VLOOKUP(B9,'BDD Estudiantes Posgrado'!$A$1:$D$200,4,0) -> 112 | G9: =VLOOKUP(B9,'Cuotas Estudiantes Pregrado'!$A$117:$M$142,13,0) -> 33 | H9: =F9/D9 -> 0.54368932 | I9: =IFERROR((((1.96^2*0.5*0.5*($D9-F9))/(F9*($D9-1)))^0.5),"") -> 0.062705273 | J9: =IFERROR((((1.65^2*0.5*0.5*($D9-F9))/(F9*($D9-1)))^0.5),"") -> 0.052787602 | K9: Encuesta | L9: =VLOOKUP($B9,'BDD Prof. Planta'!$A$1:$H$140,7,0) -> 15 | M9: 14 | N9: =VLOOKUP($B9,'BDD Prof. Planta'!$A$1:$L$140,12,0) -> 14 | O9: =M9-N9 -> 0 | P9: =N9/L9 -> 0.93333333 | Q9: =IFERROR((((1.96^2*0.5*0.5*($L9-N9))/(N9*($L9-1)))^0.5),"") -> 0.07 | R9: =IFERROR((((1.65^2*0.5*0.5*($L9-N9))/(N9*($L9-1)))^0.5),"") -> 0.058928571 | S9: Encuesta | T9: =VLOOKUP($B9,'BDD Prof. Catedra'!$A:$H,7,0) -> 23 | U9: 23 | V9: =VLOOKUP($B9,'BDD Prof. Catedra'!$A:$J,10,0) -> 21 | W9: =U9-V9 -> 2 | X9: =V9/T9 -> 0.91304348 | Y9: =IFERROR((((1.96^2*0.5*0.5*($T9-V9))/(V9*($T9-1)))^0.5),"") -> 0.064479266 | Z9: =IFERROR((((1.65^2*0.5*0.5*($T9-V9))/(V9*($T9-1)))^0.5),"") -> 0.054281015 | AA9: Encuesta
A10: 27 | B10: Comunicación Audiovisual y Multimedios | C10: FACULTAD DE COMUNICACIÓN | D10: =VLOOKUP(B10,'Cuotas Estudiantes Pregrado'!$A$4:$N$28,13,0) -> 606 | E10: =VLOOKUP(B10,'Cuotas Estudiantes Pregrado'!$A$4:$N$28,14,0) -> 259 | F10: =VLOOKUP(B10,'BDD Estudiantes Posgrado'!$A$1:$D$200,4,0) -> 267 | G10: =VLOOKUP(B10,'Cuotas Estudiantes Pregrado'!$A$117:$M$142,13,0) -> 42 | H10: =F10/D10 -> 0.44059406 | I10: =IFERROR((((1.96^2*0.5*0.5*($D10-F10))/(F10*($D10-1)))^0.5),"") -> 0.044894445 | J10: =IFERROR((((1.65^2*0.5*0.5*($D10-F10))/(F10*($D10-1)))^0.5),"") -> 0.037793793 | K10: Encuesta | L10: =VLOOKUP($B10,'BDD Prof. Planta'!$A$1:$H$140,7,0) -> 16 | M10: 16 | N10: =VLOOKUP($B10,'BDD Prof. Planta'!$A$1:$L$140,12,0) -> 16 | O10: =M10-N10 -> 0 | P10: =N10/L10 -> 1 | Q10: =IFERROR((((1.96^2*0.5*0.5*($L10-N10))/(N10*($L10-1)))^0.5),"") -> 0 | R10: =IFERROR((((1.65^2*0.5*0.5*($L10-N10))/(N10*($L10-1)))^0.5),"") -> 0 | S10: Encuesta | T10: =VLOOKUP($B10,'BDD Prof. Catedra'!$A:$H,7,0) -> 41 | U10: 40 | V10: =VLOOKUP($B10,'BDD Prof. Catedra'!$A:$J,10,0) -> 36 | W10: =U10-V10 -> 4 | X10: =V10/T10 -> 0.87804878 | Y10: =IFERROR((((1.96^2*0.5*0.5*($T10-V10))/(V10*($T10-1)))^0.5),"") -> 0.057747054 | Z10: =IFERROR((((1.65^2*0.5*0.5*($T10-V10))/(V10*($T10-1)))^0.5),"") -> 0.048613591 | AA10: Encuesta
A11: 28 | B11: Comunicación Social y Periodismo | C11: FACULTAD DE COMUNICACIÓN | D11: =VLOOKUP(B11,'Cuotas Estudiantes Pregrado'!$A$4:$N$28,13,0) -> 360 | E11: =VLOOKUP(B11,'Cuotas Estudiantes Pregrado'!$A$4:$N$28,14,0) -> 200 | F11: =VLOOKUP(B11,'BDD Estudiantes Posgrado'!$A$1:$D$200,4,0) -> 196 | G11: =VLOOKUP(B11,'Cuotas Estudiantes Pregrado'!$A$117:$M$142,13,0) -> 30 | H11: =F11/D11 -> 0.54444444 | I11: =IFERROR((((1.96^2*0.5*0.5*($D11-F11))/(F11*($D11-1)))^0.5),"") -> 0.047312156 | J11: =IFERROR((((1.65^2*0.5*0.5*($D11-F11))/(F11*($D11-1)))^0.5),"") -> 0.039829111 | K11: Encuesta | L11: =VLOOKUP($B11,'BDD Prof. Planta'!$A$1:$H$140,7,0) -> 14 | M11: 14 | N11: =VLOOKUP($B11,'BDD Prof. Planta'!$A$1:$L$140,12,0) -> 14 | O11: =M11-N11 -> 0 | P11: =N11/L11 -> 1 | Q11: =IFERROR((((1.96^2*0.5*0.5*($L11-N11))/(N11*($L11-1)))^0.5),"") -> 0 | R11: =IFERROR((((1.65^2*0.5*0.5*($L11-N11))/(N11*($L11-1)))^0.5),"") -> 0 | S11: Encuesta | T11: =VLOOKUP($B11,'BDD Prof. Catedra'!$A:$H,7,0) -> 35 | U11: 34 | V11: =VLOOKUP($B11,'BDD Prof. Catedra'!$A:$J,10,0) -> 28 | W11: =U11-V11 -> 6 | X11: =V11/T11 -> 0.8 | Y11: =IFERROR((((1.96^2*0.5*0.5*($T11-V11))/(V11*($T11-1)))^0.5),"") -> 0.084034307 | Z11: =IFERROR((((1.65^2*0.5*0.5*($T11-V11))/(V11*($T11-1)))^0.5),"") -> 0.070743166 | AA11: Encuesta
A12: 29 | B12: Ciencias Políticas | C12: FACULTAD DE DERECHO Y CIENCIAS POLÍTICAS | D12: =VLOOKUP(B12,'Cuotas Estudiantes Pregrado'!$A$4:$N$28,13,0) -> 85 | E12: =VLOOKUP(B12,'Cuotas Estudiantes Pregrado'!$A$4:$N$28,14,0) -> 71 | F12: =VLOOKUP(B12,'BDD Estudiantes Posgrado'!$A$1:$D$200,4,0) -> 68 | G12: =VLOOKUP(B12,'Cuotas Estudiantes Pregrado'!$A$117:$M$142,13,0) -> 16 | H12: =F12/D12 -> 0.8 | I12: =IFERROR((((1.96^2*0.5*0.5*($D12-F12))/(F12*($D12-1)))^0.5),"") -> 0.053463383 | J12: =IFERROR((((1.65^2*0.5*0.5*($D12-F12))/(F12*($D12-1)))^0.5),"") -> 0.04500744 | K12: Encuesta | L12: =VLOOKUP($B12,'BDD Prof. Planta'!$A$1:$H$140,7,0) -> 8 | M12: 8 | N12: =VLOOKUP($B12,'BDD Prof. Planta'!$A$1:$L$140,12,0) -> 8 | O12: =M12-N12 -> 0 | P12: =N12/L12 -> 1 | Q12: =IFERROR((((1.96^2*0.5*0.5*($L12-N12))/(N12*($L12-1)))^0.5),"") -> 0 | R12: =IFERROR((((1.65^2*0.5*0.5*($L12-N12))/(N12*($L12-1)))^0.5),"") -> 0 | S12: Encuesta | T12: =VLOOKUP($B12,'BDD Prof. Catedra'!$A:$H,7,0) -> 8 | U12: 8 | V12: =VLOOKUP($B12,'BDD Prof. Catedra'!$A:$J,10,0) -> 8 | W12: =U12-V12 -> 0 | X12: =V12/T12 -> 1 | Y12: =IFERROR((((1.96^2*0.5*0.5*($T12-V12))/(V12*($T12-1)))^0.5),"") -> 0 | Z12: =IFERROR((((1.65^2*0.5*0.5*($T12-V12))/(V12*($T12-1)))^0.5),"") -> 0 | AA12: Encuesta
A13: 30 | B13: Derecho | C13: FACULTAD DE DERECHO Y CIENCIAS POLÍTICAS | D13: =VLOOKUP(B13,'Cuotas Estudiantes Pregrado'!$A$4:$N$28,13,0) -> 306 | E13: =VLOOKUP(B13,'Cuotas Estudiantes Pregrado'!$A$4:$N$28,14,0) -> 183 | F13: =VLOOKUP(B13,'BDD Estudiantes Posgrado'!$A$1:$D$200,4,0) -> 190 | G13: =VLOOKUP(B13,'Cuotas Estudiantes Pregrado'!$A$117:$M$142,13,0) -> 20 | H13: =F13/D13 -> 0.62091503 | I13: =IFERROR((((1.96^2*0.5*0.5*($D13-F13))/(F13*($D13-1)))^0.5),"") -> 0.043845836 | J13: =IFERROR((((1.65^2*0.5*0.5*($D13-F13))/(F13*($D13-1)))^0.5),"") -> 0.036911035 | K13: Encuesta | L13: =VLOOKUP($B13,'BDD Prof. Planta'!$A$1:$H$140,7,0) -> 26 | M13: 26 | N13: =VLOOKUP($B13,'BDD Prof. Planta'!$A$1:$L$140,12,0) -> 26 | O13: =M13-N13 -> 0 | P13: =N13/L13 -> 1 | Q13: =IFERROR((((1.96^2*0.5*0.5*($L13-N13))/(N13*($L13-1)))^0.5),"") -> 0 | R13: =IFERROR((((1.65^2*0.5*0.5*($L13-N13))/(N13*($L13-1)))^0.5),"") -> 0 | S13: Encuesta | T13: =VLOOKUP($B13,'BDD Prof. Catedra'!$A:$H,7,0) -> 24 | U13: 24 | V13: =VLOOKUP($B13,'BDD Prof. Catedra'!$A:$J,10,0) -> 24 | W13: =U13-V13 -> 0 | X13: =V13/T13 -> 1 | Y13: =IFERROR((((1.96^2*0.5*0.5*($T13-V13))/(V13*($T13-1)))^0.5),"") -> 0 | Z13: =IFERROR((((1.65^2*0.5*0.5*($T13-V13))/(V13*($T13-1)))^0.5),"") -> 0 | AA13: Encuesta
A14: 31 | B14: Licenciatura en Ciencias Naturales | C14: FACULTAD DE EDUCACIÓN | D14: =VLOOKUP(B14,'Cuotas Estudiantes Pregrado'!$A$4:$N$28,13,0) -> 27 | E14: 26 | F14: =VLOOKUP(B14,'BDD Estudiantes Posgrado'!$A$1:$D$200,4,0) -> 11 | G14: =VLOOKUP(B14,'Cuotas Estudiantes Pregrado'!$A$117:$M$142,13,0) -> 18 | H14: =F14/D14 -> 0.40740741 | I14: =IFERROR((((1.96^2*0.5*0.5*($D14-F14))/(F14*($D14-1)))^0.5),"") -> 0.23179446 | J14: =IFERROR((((1.65^2*0.5*0.5*($D14-F14))/(F14*($D14-1)))^0.5),"") -> 0.19513309 | K14: Sondeo | L14: =VLOOKUP($B14,'BDD Prof. Planta'!$A$1:$H$140,7,0) -> 8 | M14: 8 | N14: =VLOOKUP($B14,'BDD Prof. Planta'!$A$1:$L$140,12,0) -> 7 | O14: =M14-N14 -> 1 | P14: =N14/L14 -> 0.875 | Q14: =IFERROR((((1.96^2*0.5*0.5*($L14-N14))/(N14*($L14-1)))^0.5),"") -> 0.14 | R14: =IFERROR((((1.65^2*0.5*0.5*($L14-N14))/(N14*($L14-1)))^0.5),"") -> 0.11785714 | S14: Encuesta | T14: =VLOOKUP($B14,'BDD Prof. Catedra'!$A:$H,7,0) -> 12 | U14: 11 | V14: =VLOOKUP($B14,'BDD Prof. Catedra'!$A:$J,10,0) -> 10 | W14: =U14-V14 -> 1 | X14: =V14/T14 -> 0.83333333 | Y14: =IFERROR((((1.96^2*0.5*0.5*($T14-V14))/(V14*($T14-1)))^0.5),"") -> 0.13214317 | Z14: =IFERROR((((1.65^2*0.5*0.5*($T14-V14))/(V14*($T14-1)))^0.5),"") -> 0.11124298 | AA14: Encuesta
A15: 32 | B15: Licenciatura en Educación Infantil | C15: FACULTAD DE EDUCACIÓN | D15: =VLOOKUP(B15,'Cuotas Estudiantes Pregrado'!$A$4:$N$28,13,0) -> 70 | E15: =VLOOKUP(B15,'Cuotas Estudiantes Pregrado'!$A$4:$N$28,14,0) -> 61 | F15: =VLOOKUP(B15,'BDD Estudiantes Posgrado'!$A$1:$D$200,4,0) -> 54 | G15: =VLOOKUP(B15,'Cuotas Estudiantes Pregrado'!$A$117:$M$142,13,0) -> 13 | H15: =F15/D15 -> 0.77142857 | I15: =IFERROR((((1.96^2*0.5*0.5*($D15-F15))/(F15*($D15-1)))^0.5),"") -> 0.064219163 | J15: =IFERROR((((1.65^2*0.5*0.5*($D15-F15))/(F15*($D15-1)))^0.5),"") -> 0.054062051 | K15: Encuesta | L15: =VLOOKUP($B15,'BDD Prof. Planta'!$A$1:$H$140,7,0) -> 9 | M15: 9 | N15: =VLOOKUP($B15,'BDD Prof. Planta'!$A$1:$L$140,12,0) -> 8 | O15: =M15-N15 -> 1 | P15: =N15/L15 -> 0.88888889 | Q15: =IFERROR((((1.96^2*0.5*0.5*($L15-N15))/(N15*($L15-1)))^0.5),"") -> 0.1225 | R15: =IFERROR((((1.65^2*0.5*0.5*($L15-N15))/(N15*($L15-1)))^0.5),"") -> 0.103125 | S15: Encuesta | T15: =VLOOKUP($B15,'BDD Prof. Catedra'!$A:$H,7,0) -> 15 | U15: 14 | V15: =VLOOKUP($B15,'BDD Prof. Catedra'!$A:$J,10,0) -> 13 | W15: =U15-V15 -> 1 | X15: =V15/T15 -> 0.86666667 | Y15: =IFERROR((((1.96^2*0.5*0.5*($T15-V15))/(V15*($T15-1)))^0.5),"") -> 0.10273191 | Z15: =IFERROR((((1.65^2*0.5*0.5*($T15-V15))/(V15*($T15-1)))^0.5),"") -> 0.086483499 | AA15: Encuesta
A16: 33 | B16: Enfermería | C16: FACULTAD DE ENFERMERÍA Y REHABILITACIÓN | D16: =VLOOKUP(B16,'Cuotas Estudiantes Pregrado'!$A$4:$N$28,13,0) -> 150 | E16: =VLOOKUP(B16,'Cuotas Estudiantes Pregrado'!$A$4:$N$28,14,0) -> 114 | F16: =VLOOKUP(B16,'BDD Estudiantes Posgrado'!$A$1:$D$200,4,0) -> 132 | G16: =VLOOKUP(B16,'Cuotas Estudiantes Pregrado'!$A$117:$M$142,13,0) -> 2 | H16: =F16/D16 -> 0.88 | I16: =IFERROR((((1.96^2*0.5*0.5*($D16-F16))/(F16*($D16-1)))^0.5),"") -> 0.029647101 | J16: =IFERROR((((1.65^2*0.5*0.5*($D16-F16))/(F16*($D16-1)))^0.5),"") -> 0.024958018 | K16: Encuesta | L16: =VLOOKUP($B16,'BDD Prof. Planta'!$A$1:$H$140,7,0) -> 14 | M16: 14 | N16: =VLOOKUP($B16,'BDD Prof. Planta'!$A$1:$L$140,12,0) -> 14 | O16: =M16-N16 -> 0 | P16: =N16/L16 -> 1 | Q16: =IFERROR((((1.96^2*0.5*0.5*($L16-N16))/(N16*($L16-1)))^0.5),"") -> 0 | R16: =IFERROR((((1.65^2*0.5*0.5*($L16-N16))/(N16*($L16-1)))^0.5),"") -> 0 | S16: Encuesta | T16: =VLOOKUP($B16,'BDD Prof. Catedra'!$A:$H,7,0) -> 6 | U16: 6 | V16: =VLOOKUP($B16,'BDD Prof. Catedra'!$A:$J,10,0) -> 5 | W16: =U16-V16 -> 1 | X16: =V16/T16 -> 0.83333333 | Y16: =IFERROR((((1.96^2*0.5*0.5*($T16-V16))/(V16*($T16-1)))^0.5),"") -> 0.196 | Z16: =IFERROR((((1.65^2*0.5*0.5*($T16-V16))/(V16*($T16-1)))^0.5),"") -> 0.165 | AA16: Encuesta
A17: 34 | B17: Fisioterapia | C17: FACULTAD DE ENFERMERÍA Y REHABILITACIÓN | D17: =VLOOKUP(B17,'Cuotas Estudiantes Pregrado'!$A$4:$N$28,13,0) -> 224 | E17: =VLOOKUP(B17,'Cuotas Estudiantes Pregrado'!$A$4:$N$28,14,0) -> 150 | F17: =VLOOKUP(B17,'BDD Estudiantes Posgrado'!$A$1:$D$200,4,0) -> 182 | G17: =VLOOKUP(B17,'Cuotas Estudiantes Pregrado'!$A$117:$M$142,13,0) -> 27 | H17: =F17/D17 -> 0.8125 | I17: =IFERROR((((1.96^2*0.5*0.5*($D17-F17))/(F17*($D17-1)))^0.5),"") -> 0.031525544 | J17: =IFERROR((((1.65^2*0.5*0.5*($D17-F17))/(F17*($D17-1)))^0.5),"") -> 0.026539361 | K17: Encuesta | L17: =VLOOKUP($B17,'BDD Prof. Planta'!$A$1:$H$140,7,0) -> 23 | M17: 23 | N17: =VLOOKUP($B17,'BDD Prof. Planta'!$A$1:$L$140,12,0) -> 23 | O17: =M17-N17 -> 0 | P17: =N17/L17 -> 1 | Q17: =IFERROR((((1.96^2*0.5*0.5*($L17-N17))/(N17*($L17-1)))^0.5),"") -> 0 | R17: =IFERROR((((1.65^2*0.5*0.5*($L17-N17))/(N17*($L17-1)))^0.5),"") -> 0 | S17: Encuesta | T17: =VLOOKUP($B17,'BDD Prof. Catedra'!$A:$H,7,0) -> 3 | U17: 3 | V17: =VLOOKUP($B17,'BDD Prof. Catedra'!$A:$J,10,0) -> 3 | W17: =U17-V17 -> 0 | X17: =V17/T17 -> 1 | Y17: =IFERROR((((1.96^2*0.5*0.5*($T17-V17))/(V17*($T17-1)))^0.5),"") -> 0 | Z17: =IFERROR((((1.65^2*0.5*0.5*($T17-V17))/(V17*($T17-1)))^0.5),"") -> 0 | AA17: Encuesta
A18: 35 | B18: Filosofía | C18: FACULTAD DE FILOSOFÍA Y CIENCIAS HUMANAS | D18: =VLOOKUP(B18,'Cuotas Estudiantes Pregrado'!$A$4:$N$28,13,0) -> 34 | E18: =VLOOKUP(B18,'Cuotas Estudiantes Pregrado'!$A$4:$N$28,14,0) -> 34 | F18: =VLOOKUP(B18,'BDD Estudiantes Posgrado'!$A$1:$D$200,4,0) -> 31 | G18: =VLOOKUP(B18,'Cuotas Estudiantes Pregrado'!$A$117:$M$142,13,0) -> 6 | H18: =F18/D18 -> 0.91176471 | I18: =IFERROR((((1.96^2*0.5*0.5*($D18-F18))/(F18*($D18-1)))^0.5),"") -> 0.053069975 | J18: =IFERROR((((1.65^2*0.5*0.5*($D18-F18))/(F18*($D18-1)))^0.5),"") -> 0.044676255 | K18: Encuesta | L18: =VLOOKUP($B18,'BDD Prof. Planta'!$A$1:$H$140,7,0) -> 5 | M18: 5 | N18: =VLOOKUP($B18,'BDD Prof. Planta'!$A$1:$L$140,12,0) -> 5 | O18: =M18-N18 -> 0 | P18: =N18/L18 -> 1 | Q18: =IFERROR((((1.96^2*0.5*0.5*($L18-N18))/(N18*($L18-1)))^0.5),"") -> 0 | R18: =IFERROR((((1.65^2*0.5*0.5*($L18-N18))/(N18*($L18-1)))^0.5),"") -> 0 | S18: Encuesta | T18: =VLOOKUP($B18,'BDD Prof. Catedra'!$A:$H,7,0) -> 5 | U18: 5 | V18: =VLOOKUP($B18,'BDD Prof. Catedra'!$A:$J,10,0) -> 5 | W18: =U18-V18 -> 0 | X18: =V18/T18 -> 1 | Y18: =IFERROR((((1.96^2*0.5*0.5*($T18-V18))/(V18*($T18-1)))^0.5),"") -> 0 | Z18: =IFERROR((((1.65^2*0.5*0.5*($T18-V18))/(V18*($T18-1)))^0.5),"") -> 0 | AA18: Encuesta
A19: 36 | B19: Ingeniería Civil | C19: FACULTAD DE INGENIERÍA | D19: =VLOOKUP(B19,'Cuotas Estudiantes Pregrado'!$A$4:$N$28,13,0) -> 114 | E19: =VLOOKUP(B19,'Cuotas Estudiantes Pregrado'!$A$4:$N$28,14,0) -> 91 | F19: =VLOOKUP(B19,'BDD Estudiantes Posgrado'!$A$1:$D$200,4,0) -> 101 | G19: =VLOOKUP(B19,'Cuotas Estudiantes Pregrado'!$A$117:$M$142,13,0) -> 3 | H19: =F19/D19 -> 0.88596491 | I19: =IFERROR((((1.96^2*0.5*0.5*($D19-F19))/(F19*($D19-1)))^0.5),"") -> 0.033074847 | J19: =IFERROR((((1.65^2*0.5*0.5*($D19-F19))/(F19*($D19-1)))^0.5),"") -> 0.027843621 | K19: Encuesta | L19: =VLOOKUP($B19,'BDD Prof. Planta'!$A$1:$H$140,7,0) -> 5 | M19: 5 | N19: =VLOOKUP($B19,'BDD Prof. Planta'!$A$1:$L$140,12,0) -> 5 | O19: =M19-N19 -> 0 | P19: =N19/L19 -> 1 | Q19: =IFERROR((((1.96^2*0.5*0.5*($L19-N19))/(N19*($L19-1)))^0.5),"") -> 0 | R19: =IFERROR((((1.65^2*0.5*0.5*($L19-N19))/(N19*($L19-1)))^0.5),"") -> 0 | S19: Encuesta | T19: =VLOOKUP($B19,'BDD Prof. Catedra'!$A:$H,7,0) -> 13 | U19: 13 | V19: =VLOOKUP($B19,'BDD Prof. Catedra'!$A:$J,10,0) -> 13 | W19: =U19-V19 -> 0 | X19: =V19/T19 -> 1 | Y19: =IFERROR((((1.96^2*0.5*0.5*($T19-V19))/(V19*($T19-1)))^0.5),"") -> 0 | Z19: =IFERROR((((1.65^2*0.5*0.5*($T19-V19))/(V19*($T19-1)))^0.5),"") -> 0 | AA19: Encuesta
A20: 37 | B20: Ingeniería de Bioproducción / Producción Agroindustrial | C20: FACULTAD DE INGENIERÍA | D20: =VLOOKUP(B20,'Cuotas Estudiantes Pregrado'!$A$4:$N$28,13,0) -> 47 | E20: 35 | F20: =VLOOKUP(B20,'BDD Estudiantes Posgrado'!$A$1:$D$200,4,0) -> 35 | G20: =VLOOKUP(B20,'Cuotas Estudiantes Pregrado'!$A$117:$M$142,13,0) -> 7 | H20: =F20/D20 -> 0.74468085 | I20: =IFERROR((((1.96^2*0.5*0.5*($D20-F20))/(F20*($D20-1)))^0.5),"") -> 0.084606506 | J20: =IFERROR((((1.65^2*0.5*0.5*($D20-F20))/(F20*($D20-1)))^0.5),"") -> 0.071224865 | K20: Encuesta | L20: =VLOOKUP($B20,'BDD Prof. Planta'!$A$1:$H$140,7,0) -> 11 | M20: 10 | N20: =VLOOKUP($B20,'BDD Prof. Planta'!$A$1:$L$140,12,0) -> 9 | O20: =M20-N20 -> 1 | P20: =N20/L20 -> 0.81818182 | Q20: =IFERROR((((1.96^2*0.5*0.5*($L20-N20))/(N20*($L20-1)))^0.5),"") -> 0.14608977 | R20: =IFERROR((((1.65^2*0.5*0.5*($L20-N20))/(N20*($L20-1)))^0.5),"") -> 0.12298374 | S20: Encuesta | T20: =VLOOKUP($B20,'BDD Prof. Catedra'!$A:$H,7,0) -> 4 | U20: 4 | V20: =VLOOKUP($B20,'BDD Prof. Catedra'!$A:$J,10,0) -> 3 | W20: =U20-V20 -> 1 | X20: =V20/T20 -> 0.75 | Y20: =IFERROR((((1.96^2*0.5*0.5*($T20-V20))/(V20*($T20-1)))^0.5),"") -> 0.32666667 | Z20: =IFERROR((((1.65^2*0.5*0.5*($T20-V20))/(V20*($T20-1)))^0.5),"") -> 0.275 | AA20: Sondeo
A21: 38 | B21: Ingeniería Industrial | C21: FACULTAD DE INGENIERÍA | D21: =VLOOKUP(B21,'Cuotas Estudiantes Pregrado'!$A$4:$N$28,13,0) -> 287 | E21: =VLOOKUP(B21,'Cuotas Estudiantes Pregrado'!$A$4:$N$28,14,0) -> 174 | F21: =VLOOKUP(B21,'BDD Estudiantes Posgrado'!$A$1:$D$200,4,0) -> 185 | G21: =VLOOKUP(B21,'Cuotas Estudiantes Pregrado'!$A$117:$M$142,13,0) -> 8 | H21: =F21/D21 -> 0.6445993 | I21: =IFERROR((((1.96^2*0.5*0.5*($D21-F21))/(F21*($D21-1)))^0.5),"") -> 0.043028606 | J21: =IFERROR((((1.65^2*0.5*0.5*($D21-F21))/(F21*($D21-1)))^0.5),"") -> 0.036223062 | K21: Encuesta | L21: =VLOOKUP($B21,'BDD Prof. Planta'!$A$1:$H$140,7,0) -> 21 | M21: 20 | N21: =VLOOKUP($B21,'BDD Prof. Planta'!$A$1:$L$140,12,0) -> 19 | O21: =M21-N21 -> 1 | P21: =N21/L21 -> 0.9047619 | Q21: =IFERROR((((1.96^2*0.5*0.5*($L21-N21))/(N21*($L21-1)))^0.5),"") -> 0.071096673 | R21: =IFERROR((((1.65^2*0.5*0.5*($L21-N21))/(N21*($L21-1)))^0.5),"") -> 0.059851791 | S21: Encuesta | T21: =VLOOKUP($B21,'BDD Prof. Catedra'!$A:$H,7,0) -> 21 | U21: 21 | V21: =VLOOKUP($B21,'BDD Prof. Catedra'!$A:$J,10,0) -> 15 | W21: =U21-V21 -> 6 | X21: =V21/T21 -> 0.71428571 | Y21: =IFERROR((((1.96^2*0.5*0.5*($T21-V21))/(V21*($T21-1)))^0.5),"") -> 0.13859293 | Z21: =IFERROR((((1.65^2*0.5*0.5*($T21-V21))/(V21*($T21-1)))^0.5),"") -> 0.11667262 | AA21: Sondeo
A22: 39 | B22: Ingeniería Informática | C22: FACULTAD DE INGENIERÍA | D22: =VLOOKUP(B22,'Cuotas Estudiantes Pregrado'!$A$4:$N$28,13,0) -> 322 | E22: =VLOOKUP(B22,'Cuotas Estudiantes Pregrado'!$A$4:$N$28,14,0) -> 189 | F22: =VLOOKUP(B22,'BDD Estudiantes Posgrado'!$A$1:$D$200,4,0) -> 209 | G22: =VLOOKUP(B22,'Cuotas Estudiantes Pregrado'!$A$117:$M$142,13,0) -> 22 | H22: =F22/D22 -> 0.64906832 | I22: =IFERROR((((1.96^2*0.5*0.5*($D22-F22))/(F22*($D22-1)))^0.5),"") -> 0.040219775 | J22: =IFERROR((((1.65^2*0.5*0.5*($D22-F22))/(F22*($D22-1)))^0.5),"") -> 0.033858484 | K22: Encuesta | L22: =VLOOKUP($B22,'BDD Prof. Planta'!$A$1:$H$140,7,0) -> 7 | M22: 7 | N22: =VLOOKUP($B22,'BDD Prof. Planta'!$A$1:$L$140,12,0) -> 7 | O22: =M22-N22 -> 0 | P22: =N22/L22 -> 1 | Q22: =IFERROR((((1.96^2*0.5*0.5*($L22-N22))/(N22*($L22-1)))^0.5),"") -> 0 | R22: =IFERROR((((1.65^2*0.5*0.5*($L22-N22))/(N22*($L22-1)))^0.5),"") -> 0 | S22: Encuesta | T22: =VLOOKUP($B22,'BDD Prof. Catedra'!$A:$H,7,0) -> 34 | U22: 33 | V22: =VLOOKUP($B22,'BDD Prof. Catedra'!$A:$J,10,0) -> 19 | W22: =U22-V22 -> 14 | X22: =V22/T22 -> 0.55882353 | Y22: =IFERROR((((1.96^2*0.5*0.5*($T22-V22))/(V22*($T22-1)))^0.5),"") -> 0.15157862 | Z22: =IFERROR((((1.65^2*0.5*0.5*($T22-V22))/(V22*($T22-1)))^0.5),"") -> 0.12760445 | AA22: Sondeo
A23: 40 | B23: Ingeniería Mecánica | C23: FACULTAD DE INGENIERÍA | D23: =VLOOKUP(B23,'Cuotas Estudiantes Pregrado'!$A$4:$N$28,13,0) -> 175 | E23: =VLOOKUP(B23,'Cuotas Estudiantes Pregrado'!$A$4:$N$28,14,0) -> 126 | F23: =VLOOKUP(B23,'BDD Estudiantes Posgrado'!$A$1:$D$200,4,0) -> 136 | G23: =VLOOKUP(B23,'Cuotas Estudiantes Pregrado'!$A$117:$M$142,13,0) -> 8 | H23: =F23/D23 -> 0.77714286 | I23: =IFERROR((((1.96^2*0.5*0.5*($D23-F23))/(F23*($D23-1)))^0.5),"") -> 0.039784536 | J23: =IFERROR((((1.65^2*0.5*0.5*($D23-F23))/(F23*($D23-1)))^0.5),"") -> 0.033492084 | K23: Encuesta | L23: =VLOOKUP($B23,'BDD Prof. Planta'!$A$1:$H$140,7,0) -> 6 | M23: 6 | N23: =VLOOKUP($B23,'BDD Prof. Planta'!$A$1:$L$140,12,0) -> 6 | O23: =M23-N23 -> 0 | P23: =N23/L23 -> 1 | Q23: =IFERROR((((1.96^2*0.5*0.5*($L23-N23))/(N23*($L23-1)))^0.5),"") -> 0 | R23: =IFERROR((((1.65^2*0.5*0.5*($L23-N23))/(N23*($L23-1)))^0.5),"") -> 0 | S23: Encuesta | T23: =VLOOKUP($B23,'BDD Prof. Catedra'!$A:$H,7,0) -> 12 | U23: 12 | V23: =VLOOKUP($B23,'BDD Prof. Catedra'!$A:$J,10,0) -> 9 | W23: =U23-V23 -> 3 | X23: =V23/T23 -> 0.75 | Y23: =IFERROR((((1.96^2*0.5*0.5*($T23-V23))/(V23*($T23-1)))^0.5),"") -> 0.1705961 | Z23: =IFERROR((((1.65^2*0.5*0.5*($T23-V23))/(V23*($T23-1)))^0.5),"") -> 0.14361407 | AA23: Sondeo
A24: 41 | B24: Ingeniería Química | C24: FACULTAD DE INGENIERÍA | D24: =VLOOKUP(B24,'Cuotas Estudiantes Pregrado'!$A$4:$N$28,13,0) -> 197 | E24: =VLOOKUP(B24,'Cuotas Estudiantes Pregrado'!$A$4:$N$28,14,0) -> 137 | F24: =VLOOKUP(B24,'BDD Estudiantes Posgrado'!$A$1:$D$200,4,0) -> 139 | G24: =VLOOKUP(B24,'Cuotas Estudiantes Pregrado'!$A$117:$M$142,13,0) -> 11 | H24: =F24/D24 -> 0.70558376 | I24: =IFERROR((((1.96^2*0.5*0.5*($D24-F24))/(F24*($D24-1)))^0.5),"") -> 0.045217301 | J24: =IFERROR((((1.65^2*0.5*0.5*($D24-F24))/(F24*($D24-1)))^0.5),"") -> 0.038065585 | K24: Encuesta | L24: =VLOOKUP($B24,'BDD Prof. Planta'!$A$1:$H$140,7,0) -> 13 | M24: 13 | N24: =VLOOKUP($B24,'BDD Prof. Planta'!$A$1:$L$140,12,0) -> 12 | O24: =M24-N24 -> 1 | P24: =N24/L24 -> 0.92307692 | Q24: =IFERROR((((1.96^2*0.5*0.5*($L24-N24))/(N24*($L24-1)))^0.5),"") -> 0.081666667 | R24: =IFERROR((((1.65^2*0.5*0.5*($L24-N24))/(N24*($L24-1)))^0.5),"") -> 0.06875 | S24: Encuesta | T24: =VLOOKUP($B24,'BDD Prof. Catedra'!$A:$H,7,0) -> 27 | U24: 27 | V24: =VLOOKUP($B24,'BDD Prof. Catedra'!$A:$J,10,0) -> 18 | W24: =U24-V24 -> 9 | X24: =V24/T24 -> 0.66666667 | Y24: =IFERROR((((1.96^2*0.5*0.5*($T24-V24))/(V24*($T24-1)))^0.5),"") -> 0.13590155 | Z24: =IFERROR((((1.65^2*0.5*0.5*($T24-V24))/(V24*($T24-1)))^0.5),"") -> 0.11440692 | AA24: Sondeo
A25: 42 | B25: Medicina | C25: FACULTAD DE MEDICINA | D25: =VLOOKUP(B25,'Cuotas Estudiantes Pregrado'!$A$4:$N$28,13,0) -> 972 | E25: =VLOOKUP(B25,'Cuotas Estudiantes Pregrado'!$A$4:$N$28,14,0) -> 306 | F25: =VLOOKUP(B25,'BDD Estudiantes Posgrado'!$A$1:$D$200,4,0) -> 679 | G25: =VLOOKUP(B25,'Cuotas Estudiantes Pregrado'!$A$117:$M$142,13,0) -> 0 | H25: =F25/D25 -> 0.69855967 | I25: =IFERROR((((1.96^2*0.5*0.5*($D25-F25))/(F25*($D25-1)))^0.5),"") -> 0.02065929 | J25: =IFERROR((((1.65^2*0.5*0.5*($D25-F25))/(F25*($D25-1)))^0.5),"") -> 0.017391749 | K25: Encuesta | L25: =VLOOKUP($B25,'BDD Prof. Planta'!$A$1:$H$140,7,0) -> 53 | M25: 50 | N25: =VLOOKUP($B25,'BDD Prof. Planta'!$A$1:$L$140,12,0) -> 48 | O25: =M25-N25 -> 2 | P25: =N25/L25 -> 0.90566038 | Q25: =IFERROR((((1.96^2*0.5*0.5*($L25-N25))/(N25*($L25-1)))^0.5),"") -> 0.043862036 | R25: =IFERROR((((1.65^2*0.5*0.5*($L25-N25))/(N25*($L25-1)))^0.5),"") -> 0.036924673 | S25: Encuesta | T25: =VLOOKUP($B25,'BDD Prof. Catedra'!$A:$H,7,0) -> 70 | U25: 61 | V25: =VLOOKUP($B25,'BDD Prof. Catedra'!$A:$J,10,0) -> 45 | W25: =U25-V25 -> 16 | X25: =V25/T25 -> 0.64285714 | Y25: =IFERROR((((1.96^2*0.5*0.5*($T25-V25))/(V25*($T25-1)))^0.5),"") -> 0.087935711 | Z25: =IFERROR((((1.65^2*0.5*0.5*($T25-V25))/(V25*($T25-1)))^0.5),"") -> 0.074027512 | AA25: Sondeo
A26: 43 | B26: Psicología | C26: FACULTAD DE PSICOLOGÍA | D26: =VLOOKUP(B26,'Cuotas Estudiantes Pregrado'!$A$4:$N$28,13,0) -> 340 | E26: =VLOOKUP(B26,'Cuotas Estudiantes Pregrado'!$A$4:$N$28,14,0) -> 195 | F26: =VLOOKUP(B26,'BDD Estudiantes Posgrado'!$A$1:$D$200,4,0) -> 205 | G26: =VLOOKUP(B26,'Cuotas Estudiantes Pregrado'!$A$117:$M$142,13,0) -> 19 | H26: =F26/D26 -> 0.60294118 | I26: =IFERROR((((1.96^2*0.5*0.5*($D26-F26))/(F26*($D26-1)))^0.5),"") -> 0.04319328 | J26: =IFERROR((((1.65^2*0.5*0.5*($D26-F26))/(F26*($D26-1)))^0.5),"") -> 0.036361689 | K26: Encuesta | L26: =VLOOKUP($B26,'BDD Prof. Planta'!$A$1:$H$140,7,0) -> 17 | M26: 16 | N26: =VLOOKUP($B26,'BDD Prof. Planta'!$A$1:$L$140,12,0) -> 16 | O26: =M26-N26 -> 0 | P26: =N26/L26 -> 0.94117647 | Q26: =IFERROR((((1.96^2*0.5*0.5*($L26-N26))/(N26*($L26-1)))^0.5),"") -> 0.06125 | R26: =IFERROR((((1.65^2*0.5*0.5*($L26-N26))/(N26*($L26-1)))^0.5),"") -> 0.0515625 | S26: Encuesta | T26: =VLOOKUP($B26,'BDD Prof. Catedra'!$A:$H,7,0) -> 14 | U26: 14 | V26: =VLOOKUP($B26,'BDD Prof. Catedra'!$A:$J,10,0) -> 13 | W26: =U26-V26 -> 1 | X26: =V26/T26 -> 0.92857143 | Y26: =IFERROR((((1.96^2*0.5*0.5*($T26-V26))/(V26*($T26-1)))^0.5),"") -> 0.075384615 | Z26: =IFERROR((((1.65^2*0.5*0.5*($T26-V26))/(V26*($T26-1)))^0.5),"") -> 0.063461538 | AA26: Encuesta
A27: 200 | B27: Ciencia de Datos | C27: FACULTAD DE INGENIERÍA | D27: =VLOOKUP(B27,'Cuotas Estudiantes Pregrado'!$A$4:$N$28,13,0) -> 26 | E27: =VLOOKUP(B27,'Cuotas Estudiantes Pregrado'!$A$4:$N$28,14,0) -> 25 | F27: =VLOOKUP(B27,'BDD Estudiantes Posgrado'!$A$1:$D$200,4,0) -> 24 | G27: =VLOOKUP(B27,'Cuotas Estudiantes Pregrado'!$A$117:$M$142,13,0) -> 3 | H27: =F27/D27 -> 0.92307692 | I27: =IFERROR((((1.96^2*0.5*0.5*($D27-F27))/(F27*($D27-1)))^0.5),"") -> 0.056580326 | J27: =IFERROR((((1.65^2*0.5*0.5*($D27-F27))/(F27*($D27-1)))^0.5),"") -> 0.047631397 | K27: Encuesta | L27: =VLOOKUP($B27,'BDD Prof. Planta'!$A$1:$H$140,7,0) -> 1 | M27: 1 | N27: =VLOOKUP($B27,'BDD Prof. Planta'!$A$1:$L$140,12,0) -> 1 | O27: =M27-N27 -> 0 | P27: =N27/L27 -> 1 | Q27: 0 | R27: =IFERROR((((1.65^2*0.5*0.5*($L27-N27))/(N27*($L27-1)))^0.5),0) -> 0 | S27: Encuesta | T27: =VLOOKUP($B27,'BDD Prof. Catedra'!$A:$H,7,0) -> 4 | U27: 4 | V27: =VLOOKUP($B27,'BDD Prof. Catedra'!$A:$J,10,0) -> 4 | W27: =U27-V27 -> 0 | X27: =V27/T27 -> 1 | Y27: =IFERROR((((1.96^2*0.5*0.5*($T27-V27))/(V27*($T27-1)))^0.5),"") -> 0 | Z27: =IFERROR((((1.65^2*0.5*0.5*($T27-V27))/(V27*($T27-1)))^0.5),"") -> 0 | AA27: Encuesta
A28: 210 | B28: Centro Internacional de Lenguas y Culturas Extranjeras | C28: CENTRO INTERNACIONAL DE LENGUAS Y CULTURAS EXTRANJERAS | I28: =IFERROR((((1.96^2*0.5*0.5*($D28-F28))/(F28*($D28-1)))^0.5),"") | J28: =IFERROR((((1.65^2*0.5*0.5*($D28-F28))/(F28*($D28-1)))^0.5),"") | L28: =VLOOKUP($B28,'BDD Prof. Planta'!$A$1:$H$140,7,0) -> 22 | M28: 21 | N28: =VLOOKUP($B28,'BDD Prof. Planta'!$A$1:$L$140,12,0) -> 20 | O28: =M28-N28 -> 1 | P28: =N28/L28 -> 0.90909091 | Q28: =IFERROR((((1.96^2*0.5*0.5*($L28-N28))/(N28*($L28-1)))^0.5),"") -> 0.067626425 | R28: =IFERROR((((1.65^2*0.5*0.5*($L28-N28))/(N28*($L28-1)))^0.5),"") -> 0.056930409 | S28: Encuesta | T28: =VLOOKUP($B28,'BDD Prof. Catedra'!$A:$H,7,0) -> 25 | U28: 24 | V28: =VLOOKUP($B28,'BDD Prof. Catedra'!$A:$J,10,0) -> 22 | W28: =U28-V28 -> 2 | X28: =V28/T28 -> 0.88 | Y28: =IFERROR((((1.96^2*0.5*0.5*($T28-V28))/(V28*($T28-1)))^0.5),"") -> 0.073870279 | Z28: =IFERROR((((1.65^2*0.5*0.5*($T28-V28))/(V28*($T28-1)))^0.5),"") -> 0.062186715 | AA28: Encuesta
A29: 211 | B29: Core Curriculum Persona y Cultura | C29: CORE CURRICULUM PERSONA Y CULTURA | I29: =IFERROR((((1.96^2*0.5*0.5*($D29-F29))/(F29*($D29-1)))^0.5),"") | J29: =IFERROR((((1.65^2*0.5*0.5*($D29-F29))/(F29*($D29-1)))^0.5),"") | L29: =VLOOKUP($B29,'BDD Prof. Planta'!$A$1:$H$140,7,0) -> 11 | M29: 11 | N29: =VLOOKUP($B29,'BDD Prof. Planta'!$A$1:$L$140,12,0) -> 11 | O29: =M29-N29 -> 0 | P29: =N29/L29 -> 1 | Q29: =IFERROR((((1.96^2*0.5*0.5*($L29-N29))/(N29*($L29-1)))^0.5),"") -> 0 | R29: =IFERROR((((1.65^2*0.5*0.5*($L29-N29))/(N29*($L29-1)))^0.5),"") -> 0 | S29: Encuesta | T29: =VLOOKUP($B29,'BDD Prof. Catedra'!$A:$H,7,0) -> 10 | U29: 10 | V29: =VLOOKUP($B29,'BDD Prof. Catedra'!$A:$J,10,0) -> 8 | W29: =U29-V29 -> 2 | X29: =V29/T29 -> 0.8 | Y29: =IFERROR((((1.96^2*0.5*0.5*($T29-V29))/(V29*($T29-1)))^0.5),"") -> 0.16333333 | Z29: =IFERROR((((1.65^2*0.5*0.5*($T29-V29))/(V29*($T29-1)))^0.5),"") -> 0.1375 | AA29: Encuesta
A30: 212 | B30: Centro de Tecnología para la Academia | C30: CENTRO DE TECNOLOGÍA PARA LA ACADEMIA | J30: =IFERROR((((1.65^2*0.5*0.5*($D30-F30))/(F30*($D30-1)))^0.5),"") | L30: =VLOOKUP($B30,'BDD Prof. Planta'!$A$1:$H$140,7,0) -> 3 | M30: 3 | N30: =VLOOKUP($B30,'BDD Prof. Planta'!$A$1:$L$140,12,0) -> 2 | O30: =M30-N30 -> 1 | P30: =N30/L30 -> 0.66666667 | Q30: =IFERROR((((1.96^2*0.5*0.5*($L30-N30))/(N30*($L30-1)))^0.5),"") -> 0.49 | R30: =IFERROR((((1.65^2*0.5*0.5*($L30-N30))/(N30*($L30-1)))^0.5),"") -> 0.4125 | S30: Sondeo | T30: =VLOOKUP($B30,'BDD Prof. Catedra'!$A:$H,7,0) -> 5 | U30: 5 | V30: =VLOOKUP($B30,'BDD Prof. Catedra'!$A:$J,10,0) -> 5 | W30: =U30-V30 -> 0 | X30: =V30/T30 -> 1 | Y30: =IFERROR((((1.96^2*0.5*0.5*($T30-V30))/(V30*($T30-1)))^0.5),"") -> 0 | Z30: =IFERROR((((1.65^2*0.5*0.5*($T30-V30))/(V30*($T30-1)))^0.5),"") -> 0 | AA30: Encuesta
A31: 44 | B31: DOCTORADO EN ADMINISTRACIÓN DE ORGANIZACIONES | C31: ESCUELA INTERNACIONAL DE CIENCIAS ECONÓMICAS Y ADMINISTRATIVAS | D31: 10 | E31: 10 | F31: =VLOOKUP(B31,'BDD Estudiantes Posgrado'!$A$1:$D$200,4,0) -> 9 | G31: =E31-F31 -> 1 | H31: =F31/D31 -> 0.9 | I31: =IFERROR((((1.96^2*0.5*0.5*($D31-F31))/(F31*($D31-1)))^0.5),"") -> 0.10888889 | J31: =IFERROR((((1.65^2*0.5*0.5*($D31-F31))/(F31*($D31-1)))^0.5),"") -> 0.091666667 | K31: Encuesta | L31: =VLOOKUP($B31,'BDD Prof. Planta'!$B$29:$G$162,6,0) -> 8 | M31: 8 | N31: =VLOOKUP($B31,'BDD Prof. Planta'!$B$29:$L$162,11,0) -> 8 | O31: =M31-N31 -> 0 | P31: =N31/L31 -> 1 | Q31: =IFERROR((((1.96^2*0.5*0.5*($L31-N31))/(N31*($L31-1)))^0.5),"") -> 0 | R31: =IFERROR((((1.65^2*0.5*0.5*($L31-N31))/(N31*($L31-1)))^0.5),"") -> 0 | S31: Encuesta | Y31: =IFERROR((((1.96^2*0.5*0.5*($T31-V31))/(V31*($T31-1)))^0.5),"") | Z31: =IFERROR((((1.65^2*0.5*0.5*($T31-V31))/(V31*($T31-1)))^0.5),"")
A32: 70 | B32: DOCTORADO EN BIOCIENCIAS | C32: FACULTAD DE INGENIERÍA | D32: 22 | E32: 21 | F32: =VLOOKUP(B32,'BDD Estudiantes Posgrado'!$A$1:$D$200,4,0) -> 7 | G32: =E32-F32 -> 14 | H32: =F32/D32 -> 0.31818182 | I32: =IFERROR((((1.96^2*0.5*0.5*($D32-F32))/(F32*($D32-1)))^0.5),"") -> 0.31304952 | J32: =IFERROR((((1.65^2*0.5*0.5*($D32-F32))/(F32*($D32-1)))^0.5),"") -> 0.26353658 | K32: Sondeo | L32: =VLOOKUP($B32,'BDD Prof. Planta'!$B$29:$G$162,6,0) -> 10 | M32: 10 | N32: =VLOOKUP($B32,'BDD Prof. Planta'!$B$29:$L$162,11,0) -> 6 | O32: =M32-N32 -> 4 | P32: =N32/L32 -> 0.6 | Q32: =IFERROR((((1.96^2*0.5*0.5*($L32-N32))/(N32*($L32-1)))^0.5),"") -> 0.26672222 | R32: =IFERROR((((1.65^2*0.5*0.5*($L32-N32))/(N32*($L32-1)))^0.5),"") -> 0.22453656 | S32: Sondeo | T32: =VLOOKUP($B32,'BDD Prof. Catedra'!B:G,6,0) -> 1 | U32: 1 | V32: =VLOOKUP($B32,'BDD Prof. Catedra'!$B:$J,9,0) -> 1 | W32: =U32-V32 -> 0 | X32: =V32/T32 -> 1 | Y32: 0 | Z32: =IFERROR((((1.65^2*0.5*0.5*($T32-V32))/(V32*($T32-1)))^0.5),0) -> 0 | AA32: Encuesta
A33: 50 | B33: DOCTORADO EN COMUNICACIÓN | C33: FACULTAD DE COMUNICACIÓN | D33: 11 | E33: 11 | F33: =VLOOKUP(B33,'BDD Estudiantes Posgrado'!$A$1:$D$200,4,0) -> 6 | G33: =E33-F33 -> 5 | H33: =F33/D33 -> 0.54545455 | I33: =IFERROR((((1.96^2*0.5*0.5*($D33-F33))/(F33*($D33-1)))^0.5),"") -> 0.28290163 | J33: =IFERROR((((1.65^2*0.5*0.5*($D33-F33))/(F33*($D33-1)))^0.5),"") -> 0.23815699 | K33: Sondeo | L33: =VLOOKUP($B33,'BDD Prof. Planta'!$B$29:$G$162,6,0) -> 5 | M33: 5 | N33: =VLOOKUP($B33,'BDD Prof. Planta'!$B$29:$L$162,11,0) -> 4 | O33: =M33-N33 -> 1 | P33: =N33/L33 -> 0.8 | Q33: =IFERROR((((1.96^2*0.5*0.5*($L33-N33))/(N33*($L33-1)))^0.5),"") -> 0.245 | R33: =IFERROR((((1.65^2*0.5*0.5*($L33-N33))/(N33*($L33-1)))^0.5),"") -> 0.20625 | S33: Encuesta | Y33: =IFERROR((((1.96^2*0.5*0.5*($T33-V33))/(V33*($T33-1)))^0.5),"") | Z33: =IFERROR((((1.65^2*0.5*0.5*($T33-V33))/(V33*($T33-1)))^0.5),"")
